Workbook
Name asiCOM: Parametros!$C$1146:$J$1172
Name cfgEmpresa: Parametros!$B$2:$L$121
Name ComprobantesCOM: Parametros!$C$190:$C$218
Name ComprobantesEXP: Parametros!$C$155:$C$162
Name ComprobantesVEN: Parametros!$C$166:$C$186
Name Distritos: Parametros!$C$1049:$C$1063
Name gruContableGAS: Parametros!$C$1146:$C$1172
Name gruContableING: Parametros!$C$1138:$C$1142
Name ingExterior: Parametros!$C$1067:$C$1106
Name IVAs: Parametros!$C$125:$C$134
Name LIQ_PER: LIQ_IMPUESTOS!$C$5:$C$16
Name ListaActividades: Parametros!$C$138:$C$150
Name meses_103: '103'!$C$5:$N$5
Name meses_104: '104'!$C$4:$N$4
Name NumDocs: Parametros!$C$52:$J$62
Name pagos: Parametros!$C$243:$C$264
Name paises: Parametros!$C$411:$C$670
Name paises17a: Parametros!$C$674:$C$763
Name paises17b: Parametros!$G$674:$G$763
Name paisesEXP: Parametros!$C$767:$C$1025
Name Regimen: Parametros!$D$39
Name Regimenes: Parametros!$C$1029:$C$1038
Name Retenciones: Parametros!$C$268:$C$407
Name sustentos: Parametros!$C$222:$C$239
Name tarifasIVA: Parametros!$E$128:$E$133
Name tbIBPs: Parametros!$C$1125:$J$1126
Name tbIBPs2: Parametros!$D$1125:$D$1126
Name tbICEs: Parametros!$C$1110:$J$1121
Name tbICEs2: Parametros!$D$1110:$D$1121
Name tbl_Empre: Parametros!$N$5:$Q$10
Name tbl_NegPop: Parametros!$S$5:$U$9
Name TipoPagos: Parametros!$C$243:$J$264
Name tiposexp: Parametros!$C$1042:$C$1045
Name XLSperiodo: Parametros!$D$20
Name XLSversion: Parametros!$D$100

Sheet Diario
A1: CONTABILIDAD - DETALLE DE ASIENTOS DE DIARIO CONTABLE
A6: Autocodigo Secuencial | B6: Numero de Transaccion | C6: Fecha Transaccion | D6: Tipo Transaccion | E6: Autocodigo Modulo | F6: Cuenta Contable | G6: Descripcion Cuenta | H6: Valor DEBE | I6: Valor HABER | J6: ND | K6: Observaciones | L6: Nota Explicativa NIIFs | M6: Glosa

Sheet Tesoreria
A1: TESORERIA - DETALLE DE COBROS Y PAGOS
A6: Autocodigo TESORERIA | B6: Autocodigo Modulo | C6: Fecha Movimiento | D6: Autocodigo Documentos | E6: Tipo Transaccion | F6: Modulo | G6: FORMA DE COBRO/PAGO | H6: Valor Transaccion | I6: No. de documento Cheque/Voucher/Ret. | J6: Nombre y/o Institucion | K6: Observaciones | L6: No. Asiento Contable | M6: No. ID / RUC | N6: Razon Social Contribuyente | O6: No. Documento / Factura SRI

Sheet Detalles
A1: DETALLE DE DOCUMENTOS EMITIDOS
A6: Autocodigo DETALLE | B6: Modulo | C6: Autocodigo Documentos | D6: Fecha Movimiento | E6: ID Articulo | F6: Codigo Principal | G6: Codigo Auxiliar | H6: Descripcion | I6: Unidad de Medida | J6: Cantidad | K6: Precio | L6: PVP Sin Subsidio | M6: Base Imponible | N6: Tipo Impuesto | O6: (%) Descto. | P6: Descuento Valor | Q6: Grava ICE | R6: ICE CODIGO | S6: ICE (%) | T6: ICE Valor Base | U6: ICE Valor Impuesto | V6: ICE EN IVA | W6: Grava IRBPNR | X6: IRBPNR CODIGO | Y6: IRBPNR (%) | Z6: IRBPNR Valor Base | AA6: IRBPNR Valor Impuesto | AB6: Valor IVA | AC6: Valor Subtotal | AD6: Atributos Adicionales | AE6: No. ID / RUC | AF6: Razon Social Contribuyente | AG6: No. Documento / Factura | AH6: Tipo Documento | AI6: Tarifa de IVA

Sheet Articulos
A1: LISTADO DE PRODUCTOS O SERVICIOS
A6: Autocodigo ARTICULOS | B6: Codigo Principal | C6: Codigo Secundario | D6: Descripcion | E6: Grupo | F6: Unidad de Medida | G6: Valor Unitario | H6: PVP sin Subsidio | I6: Impuesto IVA | J6: Descuento (%) | K6: ICE CODIGO | L6: IRBPNR CODIGO | M6: Atributos
A7: HA0000001 | B7: HONO500 | D7: HONORARIOS PROFESIONALES | E7: GENERAL | G7: 500 | H7: 0 | I7: GRAVABLE | J7: 0

Sheet Contribuyentes
A1: LISTADO DE CONTRIBUYENTES
A6: ID | B6: No. de Identificacion | C6: Tipo Identificación | D6: Apellidos y Nombres / Razon Social | E6: Direccion | F6: Tipo Proveedor | G6: Parte Relacionada | H6: Telefono | I6: email | J6: Placa / Matricula | K6: Clasificacion | L6: Cuenta Contable
A7: HC0000001 | B7: 9999999999999 | C7: F-Consumidor Final | D7: CONSUMIDOR FINAL | F7: 01-Persona Natural | G7: NO | K7: CLIENTE

Sheet Parametros
C2: Configuracion y datos de la Empresa | N2: TABLA IMPTO. REGIMEN RIMPE EMPRENDEDOR | S2: TABLA IMPTO. REGIMEN RIMPE NEG.POPULAR
N3: Año 2026 En dólares | S3: Año 2026 En dólares
B4: dt_rucemp | C4: No. de RUC | D4: 0917809451001 | G4: <== modificar por sus datos | K4: S | N4: Limite Inferior | O4: Limite Superior | P4: Imp. Frac. Básica | Q4: Tipo Marginal % | S4: Limite Inferior | T4: Limite Superior | U4: Pago Anual
B5: dt_razsoc | C5: Razon Social | D5: GARCIA RODRIGUEZ CHARLES MILTON | G5: <== modificar por sus datos | K5: S | N5: 0 | O5: 20000 | P5: 0 | Q5: 0 | S5: 0 | T5: 2500 | U5: 0
B6: dt_repleg | C6: Representante Legal | D6: GARCIA RODRIGUEZ CHARLES MILTON | G6: <== modificar por sus datos | K6: S | N6: =O5+0.01 -> 20000.01 | O6: 50000 | P6: 60 | Q6: 0.01 | S6: =T5+0.01 -> 2500.01 | T6: 5000 | U6: 5
B7: dt_cedrep | C7: Cedula Rep. Legal | D7: 0917809451001 | G7: <== modificar por sus datos | K7: S | N7: =O6+0.01 -> 50000.01 | O7: =+O6+25000 -> 75000 | P7: 360 | Q7: 0.0125 | S7: =T6+0.01 -> 5000.01 | T7: 10000 | U7: 15
B8: dt_nomcon | C8: Nombre Contador | D8: ESPINOZA TOALOMBO WILMER OLMEDO | G8: <== modificar por sus datos | K8: S | N8: =O7+0.01 -> 75000.01 | O8: =+O7+25000 -> 100000 | P8: 672.5 | Q8: 0.015 | S8: =T7+0.01 -> 10000.01 | T8: 15000 | U8: 35
B9: dt_ruccon | C9: RUC del Contador | D9: 0916540586001 | G9: <== modificar por sus datos | K9: S | N9: =O8+0.01 -> 100000.01 | O9: 200000 | P9: 1047.5 | Q9: 0.0175 | S9: =T8+0.01 -> 15000.01 | T9: 20000 | U9: 60
B10: dt_est001 | C10: No. Establecimiento_1 | D10: 001 | G10: <== No. de establecimientos ACTIVO # 1 | K10: S | N10: =O9+0.01 -> 200000.01 | O10: 300000 | P10: 2797.52 | Q10: 0.02
B11: dt_est002 | C11: No. Establecimiento_2 | G11: <== No. de establecimientos ACTIVO # 2 | K11: N
B12: dt_est003 | C12: No. Establecimiento_3 | G12: <== No. de establecimientos ACTIVO # 3 | K12: N
B13: dt_est004 | C13: No. Establecimiento_4 | G13: <== No. de establecimientos ACTIVO # 4 | K13: N
B14: dt_est005 | C14: No. Establecimiento_5 | G14: <== No. de establecimientos ACTIVO # 5 | K14: N
B15: dt_est006 | C15: No. Establecimiento_6 | G15: <== No. de establecimientos ACTIVO # 6 | K15: N
B16: dt_est007 | C16: No. Establecimiento_7 | G16: <== No. de establecimientos ACTIVO # 7 | K16: N
B17: dt_est008 | C17: No. Establecimiento_8 | G17: <== No. de establecimientos ACTIVO # 8 | K17: N
B18: dt_est009 | C18: No. Establecimiento_9 | G18: <== No. de establecimientos ACTIVO # 9 | K18: N
B19: dt_est010 | C19: No. Establecimiento_10 | G19: <== No. de establecimientos ACTIVO # 10 | K19: N
B20: dt_percon | C20: Periodo Contable: | D20: 2026 | G20: <== modificar por sus datos | K20: S
B21: dt_tipdec | C21: Tipo de Declaracion Formularios | D21: MENSUAL | G21: <== modificar por sus datos | K21: S
C23: DATOS DE USUARIO EN EL SERVIDOR WEB:
B24: dt_rutserv | C24: URL Servidor Generador ATS: | D24: SERVER_3 | G24: <== NO MODIFICAR | K24: S
B25: dt_maireg | C25: Email de Registro en Sistema: | D25: acfesvalsa@gmail.com | G25: <== cambie por su email | K25: S
B26: dt_licats | C26: Licencia de Generador ATS : | D26: Y364316907 | G26: <== cambie por su clave de generador ATS | K26: S
B27: dt_licele01 | C27: Licencia Emisor FACTURAS: | G27: <== cambie por su clave para emitir FACTURAS electronicas | K27: N
B28: dt_licele03 | C28: Licencia Emisor LIQ.COMPRAS: | G28: <== cambie por su clave para emitir LIQ.COMPRAS electronicas | K28: N
B29: dt_licele07 | C29: Licencia Emisor RETENCIONES: | G29: <== cambie por su clave para emitir RETENCIONES electronicas | K29: N
C32: Configuracion y datos para Emision Documentos Electronicos
C34: INFORMACION COMPLEMENTARIA DEL CONTRIBUYENTE EMISOR:
B35: dt_nomcom | C35: Nombre Comercial | D35: GARCIA RODRIGUEZ CHARLES MILTON | G35: <== modificar por sus datos | K35: N
B36: dt_dirmat | C36: Dirección Matriz | D36: NARANJITO AV. GUAYAQUIL Y GENERAL CORDOVA | G36: <== modificar por sus datos | K36: N
B37: dt_numtel | C37: Telefonos | D37: 0990289948 | G37: <== modificar por sus datos | K37: N
B38: dt_maipri | C38: Email de Contacto Principal | D38: acfesvalespinoza@gmail.com | G38: <== modificar por sus datos | K38: N
B39: dt_tpregi | C39: Tipo de Regimen SRI | D39: GENERAL | G39: <== modificar por sus datos | K39: N
B40: dt_especi | C40: Contribuyente Especial No. | G40: <== modificar por sus datos | K40: N
B41: dt_agente | C41: Agente de Retencion No. | G41: <== modificar por sus datos | K41: N
B42: dt_oblcon | C42: Obligado a llevar Contabilidad | D42: SI | G42: <== modificar por sus datos | K42: N
B43: cf_proleg | C43: Aplica Propina Legal | D43: NO | G43: <== modificar por sus datos | K43: N
B44: cf_propor | C44: Porcentaje de Propina Legal | D44: 10 | G44: <== modificar por sus datos | K44: N
B45: cf_ivapor | C45: Porcentaje de IVA | D45: 15 | G45: <== modificar por sus datos | K45: N
...

Sheet LIQ_IMPUESTOS
B1: =Parametros!D4&" - " & Parametros!D5 -> 0917809451001 - GARCIA RODRIGUEZ CHARLES MILTON | AO1: << INGRESAR VALOR >>
E2: DETALLE DE VENTAS | L2: Retenciones de IVA RECIBIDAS (Ventas) | M2: Retenciones de Impto. a la Renta RECIBIDAS (Ventas) | O2: DETALLE DE COMPRAS | W2: Retenciones de IVA EMITIDAS (Compras) | X2: Retenciones de Impto. a la Renta EMITIDAS (Compras) | Y2: Ret.100% IVA EMITIDAS (Compras) Sector Publico Informati | AA2: Factor proporcional I.V.A. | AB2: I.V.A. en compras utilizado | AC2: I.V.A. Causado x Pagar | AD2: Credito Tributario de I.V.A. por Compras en el presente mes | AE2: Credito Trib. I.V.A. del Periodo Anterior | AG2: Retenciones de IVA en Ventas del Presente Periodo | AH2: Credito Trib. I.V.A. para el mes Siguiente | AK2: Impuesto a pagar en el Periodo como Agente de Percepcion | AL2: Impuesto a pagar en el Periodo como Agente de Retencion | AM2: Total Valor a Pagar formulario 104 | AO2: Formulario 103
B3: Mes | C3: No. declaracion | E3: Base Imponible de Ventas NO Gravables + EXPORTACIONES | F3: Base Imponible de Ventas | G3: Subtotal Base Imponible en Ventas | H3: I.V.A. en ventas por REEMBOLSO | I3: I.V.A. en ventas GRAVABLES | J3: Total de IVA en Ventas | K3: Total de Ventas | O3: Base Imponible de Compras NO Gravable | P3: Base Imponible de Compras Gravable | Q3: Subtotal Base Imponible en Compras | R3: I.V.A. en compras por REEMBOLSO | S3: I.V.A. en compras por GASTO | T3: I.V.A. en compras para CREDITO TRIBUTARIO | U3: Total de IVA en Compras | V3: Total de Compras | AE3: Por Compras | AF3: Por Retenciones | AH3: Por Compras | AI3: Por Retenciones | AO3: En Relacion Dependencia (Casillero 302) | AP3: Valor Retenido (Casillero 352) | AQ3: Total Valor a Pagar
AE4: 0 | AF4: 0 | AG4: <<= Escribir CT del periodo anterior con simbolo negativo
B5: =VALUE("01/01/"&XLSperiodo) -> 46023 | C5: =IF(Parametros!D21="SEMESTRAL","I-Semestre",1) -> 1 | D5: =SUMIF(VENTAS!BE:BE,MONTH(B5),VENTAS!CA:CA) -> 0 | E5: =SUMIF(VENTAS!BE:BE,MONTH(B5),VENTAS!BJ:BJ)+SUMIF(EXPORTACIONES!AL:AL,MONTH(B5),EXPORTACIONES!AF:AF) -> 0 | F5: =SUMIF(VENTAS!BE:BE,MONTH(B5),VENTAS!P:P)+SUMIF(VENTAS!BE:BE,MONTH(B5),VENTAS!S:S)+SUMIF(VENTAS!BE:BE,MONTH(B5),VENTAS!V:V) -> 0 | G5: =E5+F5 -> 0 | H5: =ROUND(SUMIF(VENTAS!BE:BE,MONTH(B5),VENTAS!BK:BK),2) -> 0 | I5: =ROUND(SUMIF(VENTAS!BE:BE,MONTH(B5),VENTAS!BL:BL),2) -> 0 | J5: =SUM(H5:I5) -> 0 | K5: =G5+J5 -> 0 | L5: =SUMIF(VENTAS!BE:BE,MONTH(B5),VENTAS!AR:AR) -> 0 | M5: =SUMIF(VENTAS!BE:BE,MONTH(B5),VENTAS!AS:AS) -> 0 | O5: =SUMIF(COMPRAS!DB:DB,MONTH(B5),COMPRAS!DH:DH) -> 0 | P5: =SUMIF(COMPRAS!DB:DB,MONTH(B5),COMPRAS!X:X)+SUMIF(COMPRAS!DB:DB,MONTH(B5),COMPRAS!AA:AA)+SUMIF(COMPRAS!DB:DB,MONTH(B5),COMPRAS!AD:AD) -> 0 | Q5: =O5+P5 -> 0 | R5: =ROUND(SUMIF(COMPRAS!DB:DB,MONTH(B5),COMPRAS!DI:DI),2) -> 0 | S5: =ROUND(SUMIF(COMPRAS!DB:DB,MONTH(B5),COMPRAS!DJ:DJ),2) -> 0 | T5: =ROUND(SUMIF(COMPRAS!DB:DB,MONTH(B5),COMPRAS!DK:DK),2) -> 0 | U5: =SUM(R5:T5) -> 0 | V5: =Q5+U5 -> 0 | W5: =ROUND(SUMIF(COMPRAS!DB:DB,MONTH(B5),COMPRAS!DL:DL),2) -> 0 | X5: =ROUND(SUMIF(COMPRAS!DB:DB,MONTH(B5),COMPRAS!DN:DN),2) -> 0 | Y5: =ROUND(SUMIF(COMPRAS!DB:DB,MONTH(B5),COMPRAS!DM:DM),2) -> 0 | AA5: =IF(C5<>C6,IF(SUMIF(C$5:C5,C5,I$5:I5)>0,ROUND(((SUMIF(C$5:C5,C5,G$5:G5)-SUMIF(C$5:C5,C5,D$5:D5))/SUMIF(C$5:C5,C5,G$5:G5)),4),1),0) -> 1 | AB5: =IF(C5<>C6,ROUND(SUMIF(C$5:C5,C5,T$5:T5)*AA5,2),0) -> 0 | AC5: =IF(C5<>C6,IF((SUMIF(C$5:C5,C5,I$5:I5)-SUMIF(C$5:C5,C5,AB$5:AB5))>0,(SUMIF(C$5:C5,C5,I$5:I5)-SUMIF(C$5:C5,C5,AB$5:AB5)),0),0) -> 0 | AD5: =IF(C5<>C6,IF((SUMIF(C$5:C5,C5,I$5:I5)-SUMIF(C$5:C5,C5,AB$5:AB5))>0,0,(SUMIF(C$5:C5,C5,I$5:I5)-SUMIF(C$5:C5,C5,AB$5:AB5))),0) -> 0 | AE5: =IF(C5<>C6,AE4,0) -> 0 | AF5: =IF(C5<>C6,AF4,0) -> 0 | AG5: =-IF(C5<>C6,SUMIF(C$5:C5,C5,L$5:L5),0) -> 0 | AH5: =IF(C5<>C6,IF(SUM(AC5:AE5)<0,SUM(AC5:AE5),0),AE4) -> 0 | AI5: =IF(C5<>C6,IF(SUM(AC5:AE5)>0,IF(SUM(AC5:AG5)>0,0,SUM(AC5:AG5)),SUM(AF5:AG5)),AF4) -> 0 | AK5: =IF(C5<>C6,IF(SUM(AC5:AG5)>0,SUM(AC5:AG5),0),0) -> 0 | AL5: =IF(C5<>C6,SUMIF(C$5:C5,C5,W$5:W5),0) -> 0 | AM5: =AK5+AL5 -> 0 | AO5: 0 | AP5: 0 | AQ5: =AP5+X5 -> 0
B6: =VALUE("01/02/"&XLSperiodo) -> 46054 | C6: =IF(ISNUMBER(C5),C5+1,C5) -> 2 | D6: =SUMIF(VENTAS!BE:BE,MONTH(B6),VENTAS!CA:CA) -> 0 | E6: =SUMIF(VENTAS!BE:BE,MONTH(B6),VENTAS!BJ:BJ)+SUMIF(EXPORTACIONES!AL:AL,MONTH(B6),EXPORTACIONES!AF:AF) -> 0 | F6: =SUMIF(VENTAS!BE:BE,MONTH(B6),VENTAS!P:P)+SUMIF(VENTAS!BE:BE,MONTH(B6),VENTAS!S:S)+SUMIF(VENTAS!BE:BE,MONTH(B6),VENTAS!V:V) -> 0 | G6: =E6+F6 -> 0 | H6: =ROUND(SUMIF(VENTAS!BE:BE,MONTH(B6),VENTAS!BK:BK),2) -> 0 | I6: =ROUND(SUMIF(VENTAS!BE:BE,MONTH(B6),VENTAS!BL:BL),2) -> 0 | J6: =SUM(H6:I6) -> 0 | K6: =G6+J6 -> 0 | L6: =SUMIF(VENTAS!BE:BE,MONTH(B6),VENTAS!AR:AR) -> 0 | M6: =SUMIF(VENTAS!BE:BE,MONTH(B6),VENTAS!AS:AS) -> 0 | O6: =SUMIF(COMPRAS!DB:DB,MONTH(B6),COMPRAS!DH:DH) -> 0 | P6: =SUMIF(COMPRAS!DB:DB,MONTH(B6),COMPRAS!X:X)+SUMIF(COMPRAS!DB:DB,MONTH(B6),COMPRAS!AA:AA)+SUMIF(COMPRAS!DB:DB,MONTH(B6),COMPRAS!AD:AD) -> 0 | Q6: =O6+P6 -> 0 | R6: =ROUND(SUMIF(COMPRAS!DB:DB,MONTH(B6),COMPRAS!DI:DI),2) -> 0 | S6: =ROUND(SUMIF(COMPRAS!DB:DB,MONTH(B6),COMPRAS!DJ:DJ),2) -> 0 | T6: =ROUND(SUMIF(COMPRAS!DB:DB,MONTH(B6),COMPRAS!DK:DK),2) -> 0 | U6: =SUM(R6:T6) -> 0 | V6: =Q6+U6 -> 0 | W6: =ROUND(SUMIF(COMPRAS!DB:DB,MONTH(B6),COMPRAS!DL:DL),2) -> 0 | X6: =ROUND(SUMIF(COMPRAS!DB:DB,MONTH(B6),COMPRAS!DN:DN),2) -> 0 | Y6: =ROUND(SUMIF(COMPRAS!DB:DB,MONTH(B6),COMPRAS!DM:DM),2) -> 0 | AA6: =IF(C6<>C7,IF(SUMIF(C$5:C6,C6,I$5:I6)>0,ROUND(((SUMIF(C$5:C6,C6,G$5:G6)-SUMIF(C$5:C6,C6,D$5:D6))/SUMIF(C$5:C6,C6,G$5:G6)),4),1),0) -> 1 | AB6: =IF(C6<>C7,ROUND(SUMIF(C$5:C6,C6,T$5:T6)*AA6,2),0) -> 0 | AC6: =IF(C6<>C7,IF((SUMIF(C$5:C6,C6,I$5:I6)-SUMIF(C$5:C6,C6,AB$5:AB6))>0,(SUMIF(C$5:C6,C6,I$5:I6)-SUMIF(C$5:C6,C6,AB$5:AB6)),0),0) -> 0 | AD6: =IF(C6<>C7,IF((SUMIF(C$5:C6,C6,I$5:I6)-SUMIF(C$5:C6,C6,AB$5:AB6))>0,0,(SUMIF(C$5:C6,C6,I$5:I6)-SUMIF(C$5:C6,C6,AB$5:AB6))),0) -> 0 | AE6: =IF(C6<>C7,IF(AH5<0,AH5,0),0) -> 0 | AF6: =IF(C6<>C7,IF(AI5<0,AI5,0),0) -> 0 | AG6: =-IF(C6<>C7,SUMIF(C$5:C6,C6,L$5:L6),0) -> 0 | AH6: =IF(C6<>C7,IF(SUM(AC6:AE6)<0,SUM(AC6:AE6),0),AH5) -> 0 | AI6: =IF(C6<>C7,IF(SUM(AC6:AE6)>0,IF(SUM(AC6:AG6)>0,0,SUM(AC6:AG6)),SUM(AF6:AG6)),AI5) -> 0 | AK6: =IF(C6<>C7,IF(SUM(AC6:AG6)>0,SUM(AC6:AG6),0),0) -> 0 | AL6: =IF(C6<>C7,SUMIF(C$5:C6,C6,W$5:W6),0) -> 0 | AM6: =AK6+AL6 -> 0 | AO6: 0 | AP6: 0 | AQ6: =AP6+X6 -> 0
B7: =VALUE("01/03/"&XLSperiodo) -> 46082 | C7: =IF(ISNUMBER(C6),C6+1,C6) -> 3 | D7: =SUMIF(VENTAS!BE:BE,MONTH(B7),VENTAS!CA:CA) -> 0 | E7: =SUMIF(VENTAS!BE:BE,MONTH(B7),VENTAS!BJ:BJ)+SUMIF(EXPORTACIONES!AL:AL,MONTH(B7),EXPORTACIONES!AF:AF) -> 0 | F7: =SUMIF(VENTAS!BE:BE,MONTH(B7),VENTAS!P:P)+SUMIF(VENTAS!BE:BE,MONTH(B7),VENTAS!S:S)+SUMIF(VENTAS!BE:BE,MONTH(B7),VENTAS!V:V) -> 0 | G7: =E7+F7 -> 0 | H7: =ROUND(SUMIF(VENTAS!BE:BE,MONTH(B7),VENTAS!BK:BK),2) -> 0 | I7: =ROUND(SUMIF(VENTAS!BE:BE,MONTH(B7),VENTAS!BL:BL),2) -> 0 | J7: =SUM(H7:I7) -> 0 | K7: =G7+J7 -> 0 | L7: =SUMIF(VENTAS!BE:BE,MONTH(B7),VENTAS!AR:AR) -> 0 | M7: =SUMIF(VENTAS!BE:BE,MONTH(B7),VENTAS!AS:AS) -> 0 | O7: =SUMIF(COMPRAS!DB:DB,MONTH(B7),COMPRAS!DH:DH) -> 0 | P7: =SUMIF(COMPRAS!DB:DB,MONTH(B7),COMPRAS!X:X)+SUMIF(COMPRAS!DB:DB,MONTH(B7),COMPRAS!AA:AA)+SUMIF(COMPRAS!DB:DB,MONTH(B7),COMPRAS!AD:AD) -> 0 | Q7: =O7+P7 -> 0 | R7: =ROUND(SUMIF(COMPRAS!DB:DB,MONTH(B7),COMPRAS!DI:DI),2) -> 0 | S7: =ROUND(SUMIF(COMPRAS!DB:DB,MONTH(B7),COMPRAS!DJ:DJ),2) -> 0 | T7: =ROUND(SUMIF(COMPRAS!DB:DB,MONTH(B7),COMPRAS!DK:DK),2) -> 0 | U7: =SUM(R7:T7) -> 0 | V7: =Q7+U7 -> 0 | W7: =ROUND(SUMIF(COMPRAS!DB:DB,MONTH(B7),COMPRAS!DL:DL),2) -> 0 | X7: =ROUND(SUMIF(COMPRAS!DB:DB,MONTH(B7),COMPRAS!DN:DN),2) -> 0 | Y7: =ROUND(SUMIF(COMPRAS!DB:DB,MONTH(B7),COMPRAS!DM:DM),2) -> 0 | AA7: =IF(C7<>C8,IF(SUMIF(C$5:C7,C7,I$5:I7)>0,ROUND(((SUMIF(C$5:C7,C7,G$5:G7)-SUMIF(C$5:C7,C7,D$5:D7))/SUMIF(C$5:C7,C7,G$5:G7)),4),1),0) -> 1 | AB7: =IF(C7<>C8,ROUND(SUMIF(C$5:C7,C7,T$5:T7)*AA7,2),0) -> 0 | AC7: =IF(C7<>C8,IF((SUMIF(C$5:C7,C7,I$5:I7)-SUMIF(C$5:C7,C7,AB$5:AB7))>0,(SUMIF(C$5:C7,C7,I$5:I7)-SUMIF(C$5:C7,C7,AB$5:AB7)),0),0) -> 0 | AD7: =IF(C7<>C8,IF((SUMIF(C$5:C7,C7,I$5:I7)-SUMIF(C$5:C7,C7,AB$5:AB7))>0,0,(SUMIF(C$5:C7,C7,I$5:I7)-SUMIF(C$5:C7,C7,AB$5:AB7))),0) -> 0 | AE7: =IF(C7<>C8,IF(AH6<0,AH6,0),0) -> 0 | AF7: =IF(C7<>C8,IF(AI6<0,AI6,0),0) -> 0 | AG7: =-IF(C7<>C8,SUMIF(C$5:C7,C7,L$5:L7),0) -> 0 | AH7: =IF(C7<>C8,IF(SUM(AC7:AE7)<0,SUM(AC7:AE7),0),AH6) -> 0 | AI7: =IF(C7<>C8,IF(SUM(AC7:AE7)>0,IF(SUM(AC7:AG7)>0,0,SUM(AC7:AG7)),SUM(AF7:AG7)),AI6) -> 0 | AK7: =IF(C7<>C8,IF(SUM(AC7:AG7)>0,SUM(AC7:AG7),0),0) -> 0 | AL7: =IF(C7<>C8,SUMIF(C$5:C7,C7,W$5:W7),0) -> 0 | AM7: =AK7+AL7 -> 0 | AO7: 0 | AP7: 0 | AQ7: =AP7+X7 -> 0
B8: =VALUE("01/04/"&XLSperiodo) -> 46113 | C8: =IF(ISNUMBER(C7),C7+1,C7) -> 4 | D8: =SUMIF(VENTAS!BE:BE,MONTH(B8),VENTAS!CA:CA) -> 0 | E8: =SUMIF(VENTAS!BE:BE,MONTH(B8),VENTAS!BJ:BJ)+SUMIF(EXPORTACIONES!AL:AL,MONTH(B8),EXPORTACIONES!AF:AF) -> 0 | F8: =SUMIF(VENTAS!BE:BE,MONTH(B8),VENTAS!P:P)+SUMIF(VENTAS!BE:BE,MONTH(B8),VENTAS!S:S)+SUMIF(VENTAS!BE:BE,MONTH(B8),VENTAS!V:V) -> 23234.98 | G8: =E8+F8 -> 23234.98 | H8: =ROUND(SUMIF(VENTAS!BE:BE,MONTH(B8),VENTAS!BK:BK),2) -> 0 | I8: =ROUND(SUMIF(VENTAS!BE:BE,MONTH(B8),VENTAS!BL:BL),2) -> 3485.73 | J8: =SUM(H8:I8) -> 3485.73 | K8: =G8+J8 -> 26720.71 | L8: =SUMIF(VENTAS!BE:BE,MONTH(B8),VENTAS!AR:AR) -> 89.29 | M8: =SUMIF(VENTAS!BE:BE,MONTH(B8),VENTAS!AS:AS) -> 25.5 | O8: =SUMIF(COMPRAS!DB:DB,MONTH(B8),COMPRAS!DH:DH) -> 76.76 | P8: =SUMIF(COMPRAS!DB:DB,MONTH(B8),COMPRAS!X:X)+SUMIF(COMPRAS!DB:DB,MONTH(B8),COMPRAS!AA:AA)+SUMIF(COMPRAS!DB:DB,MONTH(B8),COMPRAS!AD:AD) -> 36472.82 | Q8: =O8+P8 -> 36549.58 | R8: =ROUND(SUMIF(COMPRAS!DB:DB,MONTH(B8),COMPRAS!DI:DI),2) -> 0 | S8: =ROUND(SUMIF(COMPRAS!DB:DB,MONTH(B8),COMPRAS!DJ:DJ),2) -> 0 | T8: =ROUND(SUMIF(COMPRAS!DB:DB,MONTH(B8),COMPRAS!DK:DK),2) -> 5200.72 | U8: =SUM(R8:T8) -> 5200.72 | V8: =Q8+U8 -> 41750.3 | W8: =ROUND(SUMIF(COMPRAS!DB:DB,MONTH(B8),COMPRAS!DL:DL),2) -> 1031.35 | X8: =ROUND(SUMIF(COMPRAS!DB:DB,MONTH(B8),COMPRAS!DN:DN),2) -> 353.92 | Y8: =ROUND(SUMIF(COMPRAS!DB:DB,MONTH(B8),COMPRAS!DM:DM),2) -> 0 | AA8: =IF(C8<>C9,IF(SUMIF(C$5:C8,C8,I$5:I8)>0,ROUND(((SUMIF(C$5:C8,C8,G$5:G8)-SUMIF(C$5:C8,C8,D$5:D8))/SUMIF(C$5:C8,C8,G$5:G8)),4),1),0) -> 1 | AB8: =IF(C8<>C9,ROUND(SUMIF(C$5:C8,C8,T$5:T8)*AA8,2),0) -> 5200.72 | AC8: =IF(C8<>C9,IF((SUMIF(C$5:C8,C8,I$5:I8)-SUMIF(C$5:C8,C8,AB$5:AB8))>0,(SUMIF(C$5:C8,C8,I$5:I8)-SUMIF(C$5:C8,C8,AB$5:AB8)),0),0) -> 0 | AD8: =IF(C8<>C9,IF((SUMIF(C$5:C8,C8,I$5:I8)-SUMIF(C$5:C8,C8,AB$5:AB8))>0,0,(SUMIF(C$5:C8,C8,I$5:I8)-SUMIF(C$5:C8,C8,AB$5:AB8))),0) -> -1714.99 | AE8: =IF(C8<>C9,IF(AH7<0,AH7,0),0) -> 0 | AF8: =IF(C8<>C9,IF(AI7<0,AI7,0),0) -> 0 | AG8: =-IF(C8<>C9,SUMIF(C$5:C8,C8,L$5:L8),0) -> -89.29 | AH8: =IF(C8<>C9,IF(SUM(AC8:AE8)<0,SUM(AC8:AE8),0),AH7) -> -1714.99 | AI8: =IF(C8<>C9,IF(SUM(AC8:AE8)>0,IF(SUM(AC8:AG8)>0,0,SUM(AC8:AG8)),SUM(AF8:AG8)),AI7) -> -89.29 | AK8: =IF(C8<>C9,IF(SUM(AC8:AG8)>0,SUM(AC8:AG8),0),0) -> 0 | AL8: =IF(C8<>C9,SUMIF(C$5:C8,C8,W$5:W8),0) -> 1031.35 | AM8: =AK8+AL8 -> 1031.35 | AO8: 0 | AP8: 0 | AQ8: =AP8+X8 -> 353.92
B9: =VALUE("01/05/"&XLSperiodo) -> 46143 | C9: =IF(ISNUMBER(C8),C8+1,C8) -> 5 | D9: =SUMIF(VENTAS!BE:BE,MONTH(B9),VENTAS!CA:CA) -> 0 | E9: =SUMIF(VENTAS!BE:BE,MONTH(B9),VENTAS!BJ:BJ)+SUMIF(EXPORTACIONES!AL:AL,MONTH(B9),EXPORTACIONES!AF:AF) -> 0 | F9: =SUMIF(VENTAS!BE:BE,MONTH(B9),VENTAS!P:P)+SUMIF(VENTAS!BE:BE,MONTH(B9),VENTAS!S:S)+SUMIF(VENTAS!BE:BE,MONTH(B9),VENTAS!V:V) -> 0 | G9: =E9+F9 -> 0 | H9: =ROUND(SUMIF(VENTAS!BE:BE,MONTH(B9),VENTAS!BK:BK),2) -> 0 | I9: =ROUND(SUMIF(VENTAS!BE:BE,MONTH(B9),VENTAS!BL:BL),2) -> 0 | J9: =SUM(H9:I9) -> 0 | K9: =G9+J9 -> 0 | L9: =SUMIF(VENTAS!BE:BE,MONTH(B9),VENTAS!AR:AR) -> 0 | M9: =SUMIF(VENTAS!BE:BE,MONTH(B9),VENTAS!AS:AS) -> 0 | O9: =SUMIF(COMPRAS!DB:DB,MONTH(B9),COMPRAS!DH:DH) -> 0 | P9: =SUMIF(COMPRAS!DB:DB,MONTH(B9),COMPRAS!X:X)+SUMIF(COMPRAS!DB:DB,MONTH(B9),COMPRAS!AA:AA)+SUMIF(COMPRAS!DB:DB,MONTH(B9),COMPRAS!AD:AD) -> 0 | Q9: =O9+P9 -> 0 | R9: =ROUND(SUMIF(COMPRAS!DB:DB,MONTH(B9),COMPRAS!DI:DI),2) -> 0 | S9: =ROUND(SUMIF(COMPRAS!DB:DB,MONTH(B9),COMPRAS!DJ:DJ),2) -> 0 | T9: =ROUND(SUMIF(COMPRAS!DB:DB,MONTH(B9),COMPRAS!DK:DK),2) -> 0 | U9: =SUM(R9:T9) -> 0 | V9: =Q9+U9 -> 0 | W9: =ROUND(SUMIF(COMPRAS!DB:DB,MONTH(B9),COMPRAS!DL:DL),2) -> 0 | X9: =ROUND(SUMIF(COMPRAS!DB:DB,MONTH(B9),COMPRAS!DN:DN),2) -> 0 | Y9: =ROUND(SUMIF(COMPRAS!DB:DB,MONTH(B9),COMPRAS!DM:DM),2) -> 0 | AA9: =IF(C9<>C10,IF(SUMIF(C$5:C9,C9,I$5:I9)>0,ROUND(((SUMIF(C$5:C9,C9,G$5:G9)-SUMIF(C$5:C9,C9,D$5:D9))/SUMIF(C$5:C9,C9,G$5:G9)),4),1),0) -> 1 | AB9: =IF(C9<>C10,ROUND(SUMIF(C$5:C9,C9,T$5:T9)*AA9,2),0) -> 0 | AC9: =IF(C9<>C10,IF((SUMIF(C$5:C9,C9,I$5:I9)-SUMIF(C$5:C9,C9,AB$5:AB9))>0,(SUMIF(C$5:C9,C9,I$5:I9)-SUMIF(C$5:C9,C9,AB$5:AB9)),0),0) -> 0 | AD9: =IF(C9<>C10,IF((SUMIF(C$5:C9,C9,I$5:I9)-SUMIF(C$5:C9,C9,AB$5:AB9))>0,0,(SUMIF(C$5:C9,C9,I$5:I9)-SUMIF(C$5:C9,C9,AB$5:AB9))),0) -> 0 | AE9: =IF(C9<>C10,IF(AH8<0,AH8,0),0) -> -1714.99 | AF9: =IF(C9<>C10,IF(AI8<0,AI8,0),0) -> -89.29 | AG9: =-IF(C9<>C10,SUMIF(C$5:C9,C9,L$5:L9),0) -> 0 | AH9: =IF(C9<>C10,IF(SUM(AC9:AE9)<0,SUM(AC9:AE9),0),AH8) -> -1714.99 | AI9: =IF(C9<>C10,IF(SUM(AC9:AE9)>0,IF(SUM(AC9:AG9)>0,0,SUM(AC9:AG9)),SUM(AF9:AG9)),AI8) -> -89.29 | AK9: =IF(C9<>C10,IF(SUM(AC9:AG9)>0,SUM(AC9:AG9),0),0) -> 0 | AL9: =IF(C9<>C10,SUMIF(C$5:C9,C9,W$5:W9),0) -> 0 | AM9: =AK9+AL9 -> 0 | AO9: 0 | AP9: 0 | AQ9: =AP9+X9 -> 0
B10: =VALUE("01/06/"&XLSperiodo) -> 46174 | C10: =IF(ISNUMBER(C9),C9+1,C9) -> 6 | D10: =SUMIF(VENTAS!BE:BE,MONTH(B10),VENTAS!CA:CA) -> 0 | E10: =SUMIF(VENTAS!BE:BE,MONTH(B10),VENTAS!BJ:BJ)+SUMIF(EXPORTACIONES!AL:AL,MONTH(B10),EXPORTACIONES!AF:AF) -> 0 | F10: =SUMIF(VENTAS!BE:BE,MONTH(B10),VENTAS!P:P)+SUMIF(VENTAS!BE:BE,MONTH(B10),VENTAS!S:S)+SUMIF(VENTAS!BE:BE,MONTH(B10),VENTAS!V:V) -> 0 | G10: =E10+F10 -> 0 | H10: =ROUND(SUMIF(VENTAS!BE:BE,MONTH(B10),VENTAS!BK:BK),2) -> 0 | I10: =ROUND(SUMIF(VENTAS!BE:BE,MONTH(B10),VENTAS!BL:BL),2) -> 0 | J10: =SUM(H10:I10) -> 0 | K10: =G10+J10 -> 0 | L10: =SUMIF(VENTAS!BE:BE,MONTH(B10),VENTAS!AR:AR) -> 0 | M10: =SUMIF(VENTAS!BE:BE,MONTH(B10),VENTAS!AS:AS) -> 0 | O10: =SUMIF(COMPRAS!DB:DB,MONTH(B10),COMPRAS!DH:DH) -> 0 | P10: =SUMIF(COMPRAS!DB:DB,MONTH(B10),COMPRAS!X:X)+SUMIF(COMPRAS!DB:DB,MONTH(B10),COMPRAS!AA:AA)+SUMIF(COMPRAS!DB:DB,MONTH(B10),COMPRAS!AD:AD) -> 0 | Q10: =O10+P10 -> 0 | R10: =ROUND(SUMIF(COMPRAS!DB:DB,MONTH(B10),COMPRAS!DI:DI),2) -> 0 | S10: =ROUND(SUMIF(COMPRAS!DB:DB,MONTH(B10),COMPRAS!DJ:DJ),2) -> 0 | T10: =ROUND(SUMIF(COMPRAS!DB:DB,MONTH(B10),COMPRAS!DK:DK),2) -> 0 | U10: =SUM(R10:T10) -> 0 | V10: =Q10+U10 -> 0 | W10: =ROUND(SUMIF(COMPRAS!DB:DB,MONTH(B10),COMPRAS!DL:DL),2) -> 0 | X10: =ROUND(SUMIF(COMPRAS!DB:DB,MONTH(B10),COMPRAS!DN:DN),2) -> 0 | Y10: =ROUND(SUMIF(COMPRAS!DB:DB,MONTH(B10),COMPRAS!DM:DM),2) -> 0 | AA10: =IF(C10<>C11,IF(SUMIF(C$5:C10,C10,I$5:I10)>0,ROUND(((SUMIF(C$5:C10,C10,G$5:G10)-SUMIF(C$5:C10,C10,D$5:D10))/SUMIF(C$5:C10,C10,G$5:G10)),4),1),0) -> 1 | AB10: =IF(C10<>C11,ROUND(SUMIF(C$5:C10,C10,T$5:T10)*AA10,2),0) -> 0 | AC10: =IF(C10<>C11,IF((SUMIF(C$5:C10,C10,I$5:I10)-SUMIF(C$5:C10,C10,AB$5:AB10))>0,(SUMIF(C$5:C10,C10,I$5:I10)-SUMIF(C$5:C10,C10,AB$5:AB10)),0),0) -> 0 | AD10: =IF(C10<>C11,IF((SUMIF(C$5:C10,C10,I$5:I10)-SUMIF(C$5:C10,C10,AB$5:AB10))>0,0,(SUMIF(C$5:C10,C10,I$5:I10)-SUMIF(C$5:C10,C10,AB$5:AB10))),0) -> 0 | AE10: =IF(C10<>C11,IF(AH9<0,AH9,0),0) -> -1714.99 | AF10: =IF(C10<>C11,IF(AI9<0,AI9,0),0) -> -89.29 | AG10: =-IF(C10<>C11,SUMIF(C$5:C10,C10,L$5:L10),0) -> 0 | AH10: =IF(C10<>C11,IF(SUM(AC10:AE10)<0,SUM(AC10:AE10),0),AH9) -> -1714.99 | AI10: =IF(C10<>C11,IF(SUM(AC10:AE10)>0,IF(SUM(AC10:AG10)>0,0,SUM(AC10:AG10)),SUM(AF10:AG10)),AI9) -> -89.29 | AK10: =IF(C10<>C11,IF(SUM(AC10:AG10)>0,SUM(AC10:AG10),0),0) -> 0 | AL10: =IF(C10<>C11,SUMIF(C$5:C10,C10,W$5:W10),0) -> 0 | AM10: =AK10+AL10 -> 0 | AO10: 0 | AP10: 0 | AQ10: =AP10+X10 -> 0
B11: =VALUE("01/07/"&XLSperiodo) -> 46204 | C11: =IF(Parametros!D21="SEMESTRAL","II-Semestre",7) -> 7 | D11: =SUMIF(VENTAS!BE:BE,MONTH(B11),VENTAS!CA:CA) -> 0 | E11: =SUMIF(VENTAS!BE:BE,MONTH(B11),VENTAS!BJ:BJ)+SUMIF(EXPORTACIONES!AL:AL,MONTH(B11),EXPORTACIONES!AF:AF) -> 0 | F11: =SUMIF(VENTAS!BE:BE,MONTH(B11),VENTAS!P:P)+SUMIF(VENTAS!BE:BE,MONTH(B11),VENTAS!S:S)+SUMIF(VENTAS!BE:BE,MONTH(B11),VENTAS!V:V) -> 0 | G11: =E11+F11 -> 0 | H11: =ROUND(SUMIF(VENTAS!BE:BE,MONTH(B11),VENTAS!BK:BK),2) -> 0 | I11: =ROUND(SUMIF(VENTAS!BE:BE,MONTH(B11),VENTAS!BL:BL),2) -> 0 | J11: =SUM(H11:I11) -> 0 | K11: =G11+J11 -> 0 | L11: =SUMIF(VENTAS!BE:BE,MONTH(B11),VENTAS!AR:AR) -> 0 | M11: =SUMIF(VENTAS!BE:BE,MONTH(B11),VENTAS!AS:AS) -> 0 | O11: =SUMIF(COMPRAS!DB:DB,MONTH(B11),COMPRAS!DH:DH) -> 0 | P11: =SUMIF(COMPRAS!DB:DB,MONTH(B11),COMPRAS!X:X)+SUMIF(COMPRAS!DB:DB,MONTH(B11),COMPRAS!AA:AA)+SUMIF(COMPRAS!DB:DB,MONTH(B11),COMPRAS!AD:AD) -> 0 | Q11: =O11+P11 -> 0 | R11: =ROUND(SUMIF(COMPRAS!DB:DB,MONTH(B11),COMPRAS!DI:DI),2) -> 0 | S11: =ROUND(SUMIF(COMPRAS!DB:DB,MONTH(B11),COMPRAS!DJ:DJ),2) -> 0 | T11: =ROUND(SUMIF(COMPRAS!DB:DB,MONTH(B11),COMPRAS!DK:DK),2) -> 0 | U11: =SUM(R11:T11) -> 0 | V11: =Q11+U11 -> 0 | W11: =ROUND(SUMIF(COMPRAS!DB:DB,MONTH(B11),COMPRAS!DL:DL),2) -> 0 | X11: =ROUND(SUMIF(COMPRAS!DB:DB,MONTH(B11),COMPRAS!DN:DN),2) -> 0 | Y11: =ROUND(SUMIF(COMPRAS!DB:DB,MONTH(B11),COMPRAS!DM:DM),2) -> 0 | AA11: =IF(C11<>C12,IF(SUMIF(C$5:C11,C11,I$5:I11)>0,ROUND(((SUMIF(C$5:C11,C11,G$5:G11)-SUMIF(C$5:C11,C11,D$5:D11))/SUMIF(C$5:C11,C11,G$5:G11)),4),1),0) -> 1 | AB11: =IF(C11<>C12,ROUND(SUMIF(C$5:C11,C11,T$5:T11)*AA11,2),0) -> 0 | AC11: =IF(C11<>C12,IF((SUMIF(C$5:C11,C11,I$5:I11)-SUMIF(C$5:C11,C11,AB$5:AB11))>0,(SUMIF(C$5:C11,C11,I$5:I11)-SUMIF(C$5:C11,C11,AB$5:AB11)),0),0) -> 0 | AD11: =IF(C11<>C12,IF((SUMIF(C$5:C11,C11,I$5:I11)-SUMIF(C$5:C11,C11,AB$5:AB11))>0,0,(SUMIF(C$5:C11,C11,I$5:I11)-SUMIF(C$5:C11,C11,AB$5:AB11))),0) -> 0 | AE11: =IF(C11<>C12,IF(AH10<0,AH10,0),0) -> -1714.99 | AF11: =IF(C11<>C12,IF(AI10<0,AI10,0),0) -> -89.29 | AG11: =-IF(C11<>C12,SUMIF(C$5:C11,C11,L$5:L11),0) -> 0 | AH11: =IF(C11<>C12,IF(SUM(AC11:AE11)<0,SUM(AC11:AE11),0),AH10) -> -1714.99 | AI11: =IF(C11<>C12,IF(SUM(AC11:AE11)>0,IF(SUM(AC11:AG11)>0,0,SUM(AC11:AG11)),SUM(AF11:AG11)),AI10) -> -89.29 | AK11: =IF(C11<>C12,IF(SUM(AC11:AG11)>0,SUM(AC11:AG11),0),0) -> 0 | AL11: =IF(C11<>C12,SUMIF(C$5:C11,C11,W$5:W11),0) -> 0 | AM11: =AK11+AL11 -> 0 | AO11: 0 | AP11: 0 | AQ11: =AP11+X11 -> 0
B12: =VALUE("01/08/"&XLSperiodo) -> 46235 | C12: =IF(ISNUMBER(C11),C11+1,C11) -> 8 | D12: =SUMIF(VENTAS!BE:BE,MONTH(B12),VENTAS!CA:CA) -> 0 | E12: =SUMIF(VENTAS!BE:BE,MONTH(B12),VENTAS!BJ:BJ)+SUMIF(EXPORTACIONES!AL:AL,MONTH(B12),EXPORTACIONES!AF:AF) -> 0 | F12: =SUMIF(VENTAS!BE:BE,MONTH(B12),VENTAS!P:P)+SUMIF(VENTAS!BE:BE,MONTH(B12),VENTAS!S:S)+SUMIF(VENTAS!BE:BE,MONTH(B12),VENTAS!V:V) -> 0 | G12: =E12+F12 -> 0 | H12: =ROUND(SUMIF(VENTAS!BE:BE,MONTH(B12),VENTAS!BK:BK),2) -> 0 | I12: =ROUND(SUMIF(VENTAS!BE:BE,MONTH(B12),VENTAS!BL:BL),2) -> 0 | J12: =SUM(H12:I12) -> 0 | K12: =G12+J12 -> 0 | L12: =SUMIF(VENTAS!BE:BE,MONTH(B12),VENTAS!AR:AR) -> 0 | M12: =SUMIF(VENTAS!BE:BE,MONTH(B12),VENTAS!AS:AS) -> 0 | O12: =SUMIF(COMPRAS!DB:DB,MONTH(B12),COMPRAS!DH:DH) -> 0 | P12: =SUMIF(COMPRAS!DB:DB,MONTH(B12),COMPRAS!X:X)+SUMIF(COMPRAS!DB:DB,MONTH(B12),COMPRAS!AA:AA)+SUMIF(COMPRAS!DB:DB,MONTH(B12),COMPRAS!AD:AD) -> 0 | Q12: =O12+P12 -> 0 | R12: =ROUND(SUMIF(COMPRAS!DB:DB,MONTH(B12),COMPRAS!DI:DI),2) -> 0 | S12: =ROUND(SUMIF(COMPRAS!DB:DB,MONTH(B12),COMPRAS!DJ:DJ),2) -> 0 | T12: =ROUND(SUMIF(COMPRAS!DB:DB,MONTH(B12),COMPRAS!DK:DK),2) -> 0 | U12: =SUM(R12:T12) -> 0 | V12: =Q12+U12 -> 0 | W12: =ROUND(SUMIF(COMPRAS!DB:DB,MONTH(B12),COMPRAS!DL:DL),2) -> 0 | X12: =ROUND(SUMIF(COMPRAS!DB:DB,MONTH(B12),COMPRAS!DN:DN),2) -> 0 | Y12: =ROUND(SUMIF(COMPRAS!DB:DB,MONTH(B12),COMPRAS!DM:DM),2) -> 0 | AA12: =IF(C12<>C13,IF(SUMIF(C$5:C12,C12,I$5:I12)>0,ROUND(((SUMIF(C$5:C12,C12,G$5:G12)-SUMIF(C$5:C12,C12,D$5:D12))/SUMIF(C$5:C12,C12,G$5:G12)),4),1),0) -> 1 | AB12: =IF(C12<>C13,ROUND(SUMIF(C$5:C12,C12,T$5:T12)*AA12,2),0) -> 0 | AC12: =IF(C12<>C13,IF((SUMIF(C$5:C12,C12,I$5:I12)-SUMIF(C$5:C12,C12,AB$5:AB12))>0,(SUMIF(C$5:C12,C12,I$5:I12)-SUMIF(C$5:C12,C12,AB$5:AB12)),0),0) -> 0 | AD12: =IF(C12<>C13,IF((SUMIF(C$5:C12,C12,I$5:I12)-SUMIF(C$5:C12,C12,AB$5:AB12))>0,0,(SUMIF(C$5:C12,C12,I$5:I12)-SUMIF(C$5:C12,C12,AB$5:AB12))),0) -> 0 | AE12: =IF(C12<>C13,IF(AH11<0,AH11,0),0) -> -1714.99 | AF12: =IF(C12<>C13,IF(AI11<0,AI11,0),0) -> -89.29 | AG12: =-IF(C12<>C13,SUMIF(C$5:C12,C12,L$5:L12),0) -> 0 | AH12: =IF(C12<>C13,IF(SUM(AC12:AE12)<0,SUM(AC12:AE12),0),AH11) -> -1714.99 | AI12: =IF(C12<>C13,IF(SUM(AC12:AE12)>0,IF(SUM(AC12:AG12)>0,0,SUM(AC12:AG12)),SUM(AF12:AG12)),AI11) -> -89.29 | AK12: =IF(C12<>C13,IF(SUM(AC12:AG12)>0,SUM(AC12:AG12),0),0) -> 0 | AL12: =IF(C12<>C13,SUMIF(C$5:C12,C12,W$5:W12),0) -> 0 | AM12: =AK12+AL12 -> 0 | AO12: 0 | AP12: 0 | AQ12: =AP12+X12 -> 0
B13: =VALUE("01/09/"&XLSperiodo) -> 46266 | C13: =IF(ISNUMBER(C12),C12+1,C12) -> 9 | D13: =SUMIF(VENTAS!BE:BE,MONTH(B13),VENTAS!CA:CA) -> 0 | E13: =SUMIF(VENTAS!BE:BE,MONTH(B13),VENTAS!BJ:BJ)+SUMIF(EXPORTACIONES!AL:AL,MONTH(B13),EXPORTACIONES!AF:AF) -> 0 | F13: =SUMIF(VENTAS!BE:BE,MONTH(B13),VENTAS!P:P)+SUMIF(VENTAS!BE:BE,MONTH(B13),VENTAS!S:S)+SUMIF(VENTAS!BE:BE,MONTH(B13),VENTAS!V:V) -> 0 | G13: =E13+F13 -> 0 | H13: =ROUND(SUMIF(VENTAS!BE:BE,MONTH(B13),VENTAS!BK:BK),2) -> 0 | I13: =ROUND(SUMIF(VENTAS!BE:BE,MONTH(B13),VENTAS!BL:BL),2) -> 0 | J13: =SUM(H13:I13) -> 0 | K13: =G13+J13 -> 0 | L13: =SUMIF(VENTAS!BE:BE,MONTH(B13),VENTAS!AR:AR) -> 0 | M13: =SUMIF(VENTAS!BE:BE,MONTH(B13),VENTAS!AS:AS) -> 0 | O13: =SUMIF(COMPRAS!DB:DB,MONTH(B13),COMPRAS!DH:DH) -> 0 | P13: =SUMIF(COMPRAS!DB:DB,MONTH(B13),COMPRAS!X:X)+SUMIF(COMPRAS!DB:DB,MONTH(B13),COMPRAS!AA:AA)+SUMIF(COMPRAS!DB:DB,MONTH(B13),COMPRAS!AD:AD) -> 0 | Q13: =O13+P13 -> 0 | R13: =ROUND(SUMIF(COMPRAS!DB:DB,MONTH(B13),COMPRAS!DI:DI),2) -> 0 | S13: =ROUND(SUMIF(COMPRAS!DB:DB,MONTH(B13),COMPRAS!DJ:DJ),2) -> 0 | T13: =ROUND(SUMIF(COMPRAS!DB:DB,MONTH(B13),COMPRAS!DK:DK),2) -> 0 | U13: =SUM(R13:T13) -> 0 | V13: =Q13+U13 -> 0 | W13: =ROUND(SUMIF(COMPRAS!DB:DB,MONTH(B13),COMPRAS!DL:DL),2) -> 0 | X13: =ROUND(SUMIF(COMPRAS!DB:DB,MONTH(B13),COMPRAS!DN:DN),2) -> 0 | Y13: =ROUND(SUMIF(COMPRAS!DB:DB,MONTH(B13),COMPRAS!DM:DM),2) -> 0 | AA13: =IF(C13<>C14,IF(SUMIF(C$5:C13,C13,I$5:I13)>0,ROUND(((SUMIF(C$5:C13,C13,G$5:G13)-SUMIF(C$5:C13,C13,D$5:D13))/SUMIF(C$5:C13,C13,G$5:G13)),4),1),0) -> 1 | AB13: =IF(C13<>C14,ROUND(SUMIF(C$5:C13,C13,T$5:T13)*AA13,2),0) -> 0 | AC13: =IF(C13<>C14,IF((SUMIF(C$5:C13,C13,I$5:I13)-SUMIF(C$5:C13,C13,AB$5:AB13))>0,(SUMIF(C$5:C13,C13,I$5:I13)-SUMIF(C$5:C13,C13,AB$5:AB13)),0),0) -> 0 | AD13: =IF(C13<>C14,IF((SUMIF(C$5:C13,C13,I$5:I13)-SUMIF(C$5:C13,C13,AB$5:AB13))>0,0,(SUMIF(C$5:C13,C13,I$5:I13)-SUMIF(C$5:C13,C13,AB$5:AB13))),0) -> 0 | AE13: =IF(C13<>C14,IF(AH12<0,AH12,0),0) -> -1714.99 | AF13: =IF(C13<>C14,IF(AI12<0,AI12,0),0) -> -89.29 | AG13: =-IF(C13<>C14,SUMIF(C$5:C13,C13,L$5:L13),0) -> 0 | AH13: =IF(C13<>C14,IF(SUM(AC13:AE13)<0,SUM(AC13:AE13),0),AH12) -> -1714.99 | AI13: =IF(C13<>C14,IF(SUM(AC13:AE13)>0,IF(SUM(AC13:AG13)>0,0,SUM(AC13:AG13)),SUM(AF13:AG13)),AI12) -> -89.29 | AK13: =IF(C13<>C14,IF(SUM(AC13:AG13)>0,SUM(AC13:AG13),0),0) -> 0 | AL13: =IF(C13<>C14,SUMIF(C$5:C13,C13,W$5:W13),0) -> 0 | AM13: =AK13+AL13 -> 0 | AO13: 0 | AP13: 0 | AQ13: =AP13+X13 -> 0
B14: =VALUE("01/10/"&XLSperiodo) -> 46296 | C14: =IF(ISNUMBER(C13),C13+1,C13) -> 10 | D14: =SUMIF(VENTAS!BE:BE,MONTH(B14),VENTAS!CA:CA) -> 0 | E14: =SUMIF(VENTAS!BE:BE,MONTH(B14),VENTAS!BJ:BJ)+SUMIF(EXPORTACIONES!AL:AL,MONTH(B14),EXPORTACIONES!AF:AF) -> 0 | F14: =SUMIF(VENTAS!BE:BE,MONTH(B14),VENTAS!P:P)+SUMIF(VENTAS!BE:BE,MONTH(B14),VENTAS!S:S)+SUMIF(VENTAS!BE:BE,MONTH(B14),VENTAS!V:V) -> 0 | G14: =E14+F14 -> 0 | H14: =ROUND(SUMIF(VENTAS!BE:BE,MONTH(B14),VENTAS!BK:BK),2) -> 0 | I14: =ROUND(SUMIF(VENTAS!BE:BE,MONTH(B14),VENTAS!BL:BL),2) -> 0 | J14: =SUM(H14:I14) -> 0 | K14: =G14+J14 -> 0 | L14: =SUMIF(VENTAS!BE:BE,MONTH(B14),VENTAS!AR:AR) -> 0 | M14: =SUMIF(VENTAS!BE:BE,MONTH(B14),VENTAS!AS:AS) -> 0 | O14: =SUMIF(COMPRAS!DB:DB,MONTH(B14),COMPRAS!DH:DH) -> 0 | P14: =SUMIF(COMPRAS!DB:DB,MONTH(B14),COMPRAS!X:X)+SUMIF(COMPRAS!DB:DB,MONTH(B14),COMPRAS!AA:AA)+SUMIF(COMPRAS!DB:DB,MONTH(B14),COMPRAS!AD:AD) -> 0 | Q14: =O14+P14 -> 0 | R14: =ROUND(SUMIF(COMPRAS!DB:DB,MONTH(B14),COMPRAS!DI:DI),2) -> 0 | S14: =ROUND(SUMIF(COMPRAS!DB:DB,MONTH(B14),COMPRAS!DJ:DJ),2) -> 0 | T14: =ROUND(SUMIF(COMPRAS!DB:DB,MONTH(B14),COMPRAS!DK:DK),2) -> 0 | U14: =SUM(R14:T14) -> 0 | V14: =Q14+U14 -> 0 | W14: =ROUND(SUMIF(COMPRAS!DB:DB,MONTH(B14),COMPRAS!DL:DL),2) -> 0 | X14: =ROUND(SUMIF(COMPRAS!DB:DB,MONTH(B14),COMPRAS!DN:DN),2) -> 0 | Y14: =ROUND(SUMIF(COMPRAS!DB:DB,MONTH(B14),COMPRAS!DM:DM),2) -> 0 | AA14: =IF(C14<>C15,IF(SUMIF(C$5:C14,C14,I$5:I14)>0,ROUND(((SUMIF(C$5:C14,C14,G$5:G14)-SUMIF(C$5:C14,C14,D$5:D14))/SUMIF(C$5:C14,C14,G$5:G14)),4),1),0) -> 1 | AB14: =IF(C14<>C15,ROUND(SUMIF(C$5:C14,C14,T$5:T14)*AA14,2),0) -> 0 | AC14: =IF(C14<>C15,IF((SUMIF(C$5:C14,C14,I$5:I14)-SUMIF(C$5:C14,C14,AB$5:AB14))>0,(SUMIF(C$5:C14,C14,I$5:I14)-SUMIF(C$5:C14,C14,AB$5:AB14)),0),0) -> 0 | AD14: =IF(C14<>C15,IF((SUMIF(C$5:C14,C14,I$5:I14)-SUMIF(C$5:C14,C14,AB$5:AB14))>0,0,(SUMIF(C$5:C14,C14,I$5:I14)-SUMIF(C$5:C14,C14,AB$5:AB14))),0) -> 0 | AE14: =IF(C14<>C15,IF(AH13<0,AH13,0),0) -> -1714.99 | AF14: =IF(C14<>C15,IF(AI13<0,AI13,0),0) -> -89.29 | AG14: =-IF(C14<>C15,SUMIF(C$5:C14,C14,L$5:L14),0) -> 0 | AH14: =IF(C14<>C15,IF(SUM(AC14:AE14)<0,SUM(AC14:AE14),0),AH13) -> -1714.99 | AI14: =IF(C14<>C15,IF(SUM(AC14:AE14)>0,IF(SUM(AC14:AG14)>0,0,SUM(AC14:AG14)),SUM(AF14:AG14)),AI13) -> -89.29 | AK14: =IF(C14<>C15,IF(SUM(AC14:AG14)>0,SUM(AC14:AG14),0),0) -> 0 | AL14: =IF(C14<>C15,SUMIF(C$5:C14,C14,W$5:W14),0) -> 0 | AM14: =AK14+AL14 -> 0 | AO14: 0 | AP14: 0 | AQ14: =AP14+X14 -> 0
B15: =VALUE("01/11/"&XLSperiodo) -> 46327 | C15: =IF(ISNUMBER(C14),C14+1,C14) -> 11 | D15: =SUMIF(VENTAS!BE:BE,MONTH(B15),VENTAS!CA:CA) -> 0 | E15: =SUMIF(VENTAS!BE:BE,MONTH(B15),VENTAS!BJ:BJ)+SUMIF(EXPORTACIONES!AL:AL,MONTH(B15),EXPORTACIONES!AF:AF) -> 0 | F15: =SUMIF(VENTAS!BE:BE,MONTH(B15),VENTAS!P:P)+SUMIF(VENTAS!BE:BE,MONTH(B15),VENTAS!S:S)+SUMIF(VENTAS!BE:BE,MONTH(B15),VENTAS!V:V) -> 0 | G15: =E15+F15 -> 0 | H15: =ROUND(SUMIF(VENTAS!BE:BE,MONTH(B15),VENTAS!BK:BK),2) -> 0 | I15: =ROUND(SUMIF(VENTAS!BE:BE,MONTH(B15),VENTAS!BL:BL),2) -> 0 | J15: =SUM(H15:I15) -> 0 | K15: =G15+J15 -> 0 | L15: =SUMIF(VENTAS!BE:BE,MONTH(B15),VENTAS!AR:AR) -> 0 | M15: =SUMIF(VENTAS!BE:BE,MONTH(B15),VENTAS!AS:AS) -> 0 | O15: =SUMIF(COMPRAS!DB:DB,MONTH(B15),COMPRAS!DH:DH) -> 0 | P15: =SUMIF(COMPRAS!DB:DB,MONTH(B15),COMPRAS!X:X)+SUMIF(COMPRAS!DB:DB,MONTH(B15),COMPRAS!AA:AA)+SUMIF(COMPRAS!DB:DB,MONTH(B15),COMPRAS!AD:AD) -> 0 | Q15: =O15+P15 -> 0 | R15: =ROUND(SUMIF(COMPRAS!DB:DB,MONTH(B15),COMPRAS!DI:DI),2) -> 0 | S15: =ROUND(SUMIF(COMPRAS!DB:DB,MONTH(B15),COMPRAS!DJ:DJ),2) -> 0 | T15: =ROUND(SUMIF(COMPRAS!DB:DB,MONTH(B15),COMPRAS!DK:DK),2) -> 0 | U15: =SUM(R15:T15) -> 0 | V15: =Q15+U15 -> 0 | W15: =ROUND(SUMIF(COMPRAS!DB:DB,MONTH(B15),COMPRAS!DL:DL),2) -> 0 | X15: =ROUND(SUMIF(COMPRAS!DB:DB,MONTH(B15),COMPRAS!DN:DN),2) -> 0 | Y15: =ROUND(SUMIF(COMPRAS!DB:DB,MONTH(B15),COMPRAS!DM:DM),2) -> 0 | AA15: =IF(C15<>C16,IF(SUMIF(C$5:C15,C15,I$5:I15)>0,ROUND(((SUMIF(C$5:C15,C15,G$5:G15)-SUMIF(C$5:C15,C15,D$5:D15))/SUMIF(C$5:C15,C15,G$5:G15)),4),1),0) -> 1 | AB15: =IF(C15<>C16,ROUND(SUMIF(C$5:C15,C15,T$5:T15)*AA15,2),0) -> 0 | AC15: =IF(C15<>C16,IF((SUMIF(C$5:C15,C15,I$5:I15)-SUMIF(C$5:C15,C15,AB$5:AB15))>0,(SUMIF(C$5:C15,C15,I$5:I15)-SUMIF(C$5:C15,C15,AB$5:AB15)),0),0) -> 0 | AD15: =IF(C15<>C16,IF((SUMIF(C$5:C15,C15,I$5:I15)-SUMIF(C$5:C15,C15,AB$5:AB15))>0,0,(SUMIF(C$5:C15,C15,I$5:I15)-SUMIF(C$5:C15,C15,AB$5:AB15))),0) -> 0 | AE15: =IF(C15<>C16,IF(AH14<0,AH14,0),0) -> -1714.99 | AF15: =IF(C15<>C16,IF(AI14<0,AI14,0),0) -> -89.29 | AG15: =-IF(C15<>C16,SUMIF(C$5:C15,C15,L$5:L15),0) -> 0 | AH15: =IF(C15<>C16,IF(SUM(AC15:AE15)<0,SUM(AC15:AE15),0),AH14) -> -1714.99 | AI15: =IF(C15<>C16,IF(SUM(AC15:AE15)>0,IF(SUM(AC15:AG15)>0,0,SUM(AC15:AG15)),SUM(AF15:AG15)),AI14) -> -89.29 | AK15: =IF(C15<>C16,IF(SUM(AC15:AG15)>0,SUM(AC15:AG15),0),0) -> 0 | AL15: =IF(C15<>C16,SUMIF(C$5:C15,C15,W$5:W15),0) -> 0 | AM15: =AK15+AL15 -> 0 | AO15: 0 | AP15: 0 | AQ15: =AP15+X15 -> 0
B16: =VALUE("01/12/"&XLSperiodo) -> 46357 | C16: =IF(ISNUMBER(C15),C15+1,C15) -> 12 | D16: =SUMIF(VENTAS!BE:BE,MONTH(B16),VENTAS!CA:CA) -> 0 | E16: =SUMIF(VENTAS!BE:BE,MONTH(B16),VENTAS!BJ:BJ)+SUMIF(EXPORTACIONES!AL:AL,MONTH(B16),EXPORTACIONES!AF:AF) -> 0 | F16: =SUMIF(VENTAS!BE:BE,MONTH(B16),VENTAS!P:P)+SUMIF(VENTAS!BE:BE,MONTH(B16),VENTAS!S:S)+SUMIF(VENTAS!BE:BE,MONTH(B16),VENTAS!V:V) -> 0 | G16: =E16+F16 -> 0 | H16: =ROUND(SUMIF(VENTAS!BE:BE,MONTH(B16),VENTAS!BK:BK),2) -> 0 | I16: =ROUND(SUMIF(VENTAS!BE:BE,MONTH(B16),VENTAS!BL:BL),2) -> 0 | J16: =SUM(H16:I16) -> 0 | K16: =G16+J16 -> 0 | L16: =SUMIF(VENTAS!BE:BE,MONTH(B16),VENTAS!AR:AR) -> 0 | M16: =SUMIF(VENTAS!BE:BE,MONTH(B16),VENTAS!AS:AS) -> 0 | O16: =SUMIF(COMPRAS!DB:DB,MONTH(B16),COMPRAS!DH:DH) -> 0 | P16: =SUMIF(COMPRAS!DB:DB,MONTH(B16),COMPRAS!X:X)+SUMIF(COMPRAS!DB:DB,MONTH(B16),COMPRAS!AA:AA)+SUMIF(COMPRAS!DB:DB,MONTH(B16),COMPRAS!AD:AD) -> 0 | Q16: =O16+P16 -> 0 | R16: =ROUND(SUMIF(COMPRAS!DB:DB,MONTH(B16),COMPRAS!DI:DI),2) -> 0 | S16: =ROUND(SUMIF(COMPRAS!DB:DB,MONTH(B16),COMPRAS!DJ:DJ),2) -> 0 | T16: =ROUND(SUMIF(COMPRAS!DB:DB,MONTH(B16),COMPRAS!DK:DK),2) -> 0 | U16: =SUM(R16:T16) -> 0 | V16: =Q16+U16 -> 0 | W16: =ROUND(SUMIF(COMPRAS!DB:DB,MONTH(B16),COMPRAS!DL:DL),2) -> 0 | X16: =ROUND(SUMIF(COMPRAS!DB:DB,MONTH(B16),COMPRAS!DN:DN),2) -> 0 | Y16: =ROUND(SUMIF(COMPRAS!DB:DB,MONTH(B16),COMPRAS!DM:DM),2) -> 0 | AA16: =IF(C16<>C17,IF(SUMIF(C$5:C16,C16,I$5:I16)>0,ROUND(((SUMIF(C$5:C16,C16,G$5:G16)-SUMIF(C$5:C16,C16,D$5:D16))/SUMIF(C$5:C16,C16,G$5:G16)),4),1),0) -> 1 | AB16: =ROUND(SUMIF(C$5:C16,C16,T$5:T16)*AA16,2) -> 0 | AC16: =IF(C16<>C17,IF((SUMIF(C$5:C16,C16,I$5:I16)-SUMIF(C$5:C16,C16,AB$5:AB16))>0,(SUMIF(C$5:C16,C16,I$5:I16)-SUMIF(C$5:C16,C16,AB$5:AB16)),0),0) -> 0 | AD16: =IF(C16<>C17,IF((SUMIF(C$5:C16,C16,I$5:I16)-SUMIF(C$5:C16,C16,AB$5:AB16))>0,0,(SUMIF(C$5:C16,C16,I$5:I16)-SUMIF(C$5:C16,C16,AB$5:AB16))),0) -> 0 | AE16: =IF(C16<>C17,IF(AH15<0,AH15,0),0) -> -1714.99 | AF16: =IF(C16<>C17,IF(AI15<0,AI15,0),0) -> -89.29 | AG16: =-IF(C16<>C17,SUMIF(C$5:C16,C16,L$5:L16),0) -> 0 | AH16: =IF(C16<>C17,IF(SUM(AC16:AE16)<0,SUM(AC16:AE16),0),AH15) -> -1714.99 | AI16: =IF(C16<>C17,IF(SUM(AC16:AE16)>0,IF(SUM(AC16:AG16)>0,0,SUM(AC16:AG16)),SUM(AF16:AG16)),AI15) -> -89.29 | AK16: =IF(C16<>C17,IF(SUM(AC16:AG16)>0,SUM(AC16:AG16),0),0) -> 0 | AL16: =IF(C16<>C17,SUMIF(C$5:C16,C16,W$5:W16),0) -> 0 | AM16: =AK16+AL16 -> 0 | AO16: 0 | AP16: 0 | AQ16: =AP16+X16 -> 0
E18: =SUM(E5:E17) -> 0 | F18: =SUM(F5:F17) -> 23234.98 | G18: =SUM(G5:G17) -> 23234.98 | H18: =SUM(H5:H17) -> 0 | I18: =SUM(I5:I17) -> 3485.73 | J18: =SUM(J5:J17) -> 3485.73 | K18: =SUM(K5:K17) -> 26720.71 | L18: =SUM(L5:L17) -> 89.29 | M18: =SUM(M5:M17) -> 25.5 | O18: =SUM(O5:O17) -> 76.76 | P18: =SUM(P5:P17) -> 36472.82 | Q18: =SUM(Q5:Q17) -> 36549.58 | R18: =SUM(R5:R17) -> 0 | S18: =SUM(S5:S17) -> 0 | T18: =SUM(T5:T17) -> 5200.72 | U18: =SUM(U5:U17) -> 5200.72 | V18: =SUM(V5:V17) -> 41750.3 | ... Y18: =SUM(Y5:Y17) -> 0 | AB18: =SUM(AB5:AB17) -> 5200.72 | AC18: =SUM(AC5:AC17) -> 0 | AD18: =SUM(AD5:AD17) -> -1714.99 | AE18: =SUM(AE5:AE17) -> -13719.92 | AF18: =SUM(AF5:AF17) -> -714.32 | AG18: =SUM(AG5:AG17) -> -89.29 | AH18: =SUM(AH5:AH17) -> -15434.91 | AI18: =SUM(AI5:AI17) -> -803.61 | AK18: =SUM(AK5:AK17) -> 0 | AL18: =SUM(AL5:AL17) -> 1031.35 | AM18: =SUM(AM5:AM17) -> 1031.35 | AO18: =SUM(AO5:AO17) -> 0 | AP18: =SUM(AP5:AP17) -> 0 | AQ18: =SUM(AQ5:AQ17) -> 353.92
B20: TIPO DE REGIMEN:
B21: RIMPE EMPRENDEDOR
A22: =+Parametros!C139 -> RIMPE | K22: 1er SEMESTRE (ENE-JUN) | L22: 2do SEMESTRE (JUL-DIC) | M22: TOTAL ANUAL
A23: SUBTOTAL INGRESOS | K23: =SUM(K24:K26) -> 0 | L23: =SUM(L24:L26) -> 0 | M23: =SUM(M24:M26) -> 0
B24: 18-Documentos autorizados utilizados en ventas excepto N/C N/D | K24: =SUMIFS(VENTAS!$M:$M,VENTAS!$AI:$AI,$A$22,VENTAS!$H:$H,$B24,VENTAS!$BE:$BE,"<7")+SUMIFS(VENTAS!$O:$O,VENTAS!$AI:$AI,$A$22,VENTAS!$H:$H,$B24,VENTAS!$BE:$BE,"<7")+SUMIFS(VENTAS!$P:$P,VENTAS!$AI:$AI,$A$22,VENTAS!$H:$H,$B24,VENTAS!$BE:$BE,"<7")+SUMIFS(VENTAS!$S:$S,VENTAS!$AI:$AI,$A$22,VENTAS!$H:$H,$B24,VENTAS!$BE:$BE,"<7")+SUMIFS(VENTAS!$V:$V,VENTAS!$AI:$AI,$A$22,VENTAS!$H:$H,$B24,VENTAS!$BE:$BE,"<7") -> 0 | L24: =SUMIFS(VENTAS!$M:$M,VENTAS!$AI:$AI,$A$22,VENTAS!$H:$H,$B24,VENTAS!$BE:$BE,">6")+SUMIFS(VENTAS!$O:$O,VENTAS!$AI:$AI,$A$22,VENTAS!$H:$H,$B24,VENTAS!$BE:$BE,">6")+SUMIFS(VENTAS!$P:$P,VENTAS!$AI:$AI,$A$22,VENTAS!$H:$H,$B24,VENTAS!$BE:$BE,">6")+SUMIFS(VENTAS!$S:$S,VENTAS!$AI:$AI,$A$22,VENTAS!$H:$H,$B24,VENTAS!$BE:$BE,">6")+SUMIFS(VENTAS!$V:$V,VENTAS!$AI:$AI,$A$22,VENTAS!$H:$H,$B24,VENTAS!$BE:$BE,">6") -> 0 | M24: =K24+L24 -> 0
B25: 370-Factura operadora transporte / socio | K25: =SUMIFS(VENTAS!$M:$M,VENTAS!$AI:$AI,$A$22,VENTAS!$H:$H,$B25,VENTAS!$BE:$BE,"<7")+SUMIFS(VENTAS!$O:$O,VENTAS!$AI:$AI,$A$22,VENTAS!$H:$H,$B25,VENTAS!$BE:$BE,"<7")+SUMIFS(VENTAS!$P:$P,VENTAS!$AI:$AI,$A$22,VENTAS!$H:$H,$B25,VENTAS!$BE:$BE,"<7")+SUMIFS(VENTAS!$S:$S,VENTAS!$AI:$AI,$A$22,VENTAS!$H:$H,$B25,VENTAS!$BE:$BE,"<7")+SUMIFS(VENTAS!$V:$V,VENTAS!$AI:$AI,$A$22,VENTAS!$H:$H,$B25,VENTAS!$BE:$BE,"<7") -> 0 | L25: =SUMIFS(VENTAS!$M:$M,VENTAS!$AI:$AI,$A$22,VENTAS!$H:$H,$B25,VENTAS!$BE:$BE,">6")+SUMIFS(VENTAS!$O:$O,VENTAS!$AI:$AI,$A$22,VENTAS!$H:$H,$B25,VENTAS!$BE:$BE,">6")+SUMIFS(VENTAS!$P:$P,VENTAS!$AI:$AI,$A$22,VENTAS!$H:$H,$B25,VENTAS!$BE:$BE,">6")+SUMIFS(VENTAS!$S:$S,VENTAS!$AI:$AI,$A$22,VENTAS!$H:$H,$B25,VENTAS!$BE:$BE,">6")+SUMIFS(VENTAS!$V:$V,VENTAS!$AI:$AI,$A$22,VENTAS!$H:$H,$B25,VENTAS!$BE:$BE,">6") -> 0 | M25: =K25+L25 -> 0
K26: =SUMIFS(VENTAS!$M:$M,VENTAS!$AI:$AI,$A$22,VENTAS!$H:$H,$B26,VENTAS!$BE:$BE,"<7")+SUMIFS(VENTAS!$O:$O,VENTAS!$AI:$AI,$A$22,VENTAS!$H:$H,$B26,VENTAS!$BE:$BE,"<7")+SUMIFS(VENTAS!$P:$P,VENTAS!$AI:$AI,$A$22,VENTAS!$H:$H,$B26,VENTAS!$BE:$BE,"<7")+SUMIFS(VENTAS!$S:$S,VENTAS!$AI:$AI,$A$22,VENTAS!$H:$H,$B26,VENTAS!$BE:$BE,"<7")+SUMIFS(VENTAS!$V:$V,VENTAS!$AI:$AI,$A$22,VENTAS!$H:$H,$B26,VENTAS!$BE:$BE,"<7") -> 0 | L26: =SUMIFS(VENTAS!$M:$M,VENTAS!$AI:$AI,$A$22,VENTAS!$H:$H,$B26,VENTAS!$BE:$BE,">6")+SUMIFS(VENTAS!$O:$O,VENTAS!$AI:$AI,$A$22,VENTAS!$H:$H,$B26,VENTAS!$BE:$BE,">6")+SUMIFS(VENTAS!$P:$P,VENTAS!$AI:$AI,$A$22,VENTAS!$H:$H,$B26,VENTAS!$BE:$BE,">6")+SUMIFS(VENTAS!$S:$S,VENTAS!$AI:$AI,$A$22,VENTAS!$H:$H,$B26,VENTAS!$BE:$BE,">6")+SUMIFS(VENTAS!$V:$V,VENTAS!$AI:$AI,$A$22,VENTAS!$H:$H,$B26,VENTAS!$BE:$BE,">6") -> 0 | M26: =K26+L26 -> 0
A27: (-)DEVOLUCIONES | K27: =SUM(K28:K30) -> 0 | L27: =SUM(L28:L30) -> 0 | M27: =SUM(M28:M30) -> 0
B28: 04-Nota de credito | K28: =SUMIFS(VENTAS!$M:$M,VENTAS!$AI:$AI,$A$22,VENTAS!$H:$H,$B28,VENTAS!$BE:$BE,"<7")+SUMIFS(VENTAS!$O:$O,VENTAS!$AI:$AI,$A$22,VENTAS!$H:$H,$B28,VENTAS!$BE:$BE,"<7")+SUMIFS(VENTAS!$P:$P,VENTAS!$AI:$AI,$A$22,VENTAS!$H:$H,$B28,VENTAS!$BE:$BE,"<7")+SUMIFS(VENTAS!$S:$S,VENTAS!$AI:$AI,$A$22,VENTAS!$H:$H,$B28,VENTAS!$BE:$BE,"<7")+SUMIFS(VENTAS!$V:$V,VENTAS!$AI:$AI,$A$22,VENTAS!$H:$H,$B28,VENTAS!$BE:$BE,"<7") -> 0 | L28: =SUMIFS(VENTAS!$M:$M,VENTAS!$AI:$AI,$A$22,VENTAS!$H:$H,$B28,VENTAS!$BE:$BE,">6")+SUMIFS(VENTAS!$O:$O,VENTAS!$AI:$AI,$A$22,VENTAS!$H:$H,$B28,VENTAS!$BE:$BE,">6")+SUMIFS(VENTAS!$P:$P,VENTAS!$AI:$AI,$A$22,VENTAS!$H:$H,$B28,VENTAS!$BE:$BE,">6")+SUMIFS(VENTAS!$S:$S,VENTAS!$AI:$AI,$A$22,VENTAS!$H:$H,$B28,VENTAS!$BE:$BE,">6")+SUMIFS(VENTAS!$V:$V,VENTAS!$AI:$AI,$A$22,VENTAS!$H:$H,$B28,VENTAS!$BE:$BE,">6") -> 0 | M28: =K28+L28 -> 0
B29: 372-Nota de crédito operadora transporte / socio | K29: =SUMIFS(VENTAS!$M:$M,VENTAS!$AI:$AI,$A$22,VENTAS!$H:$H,$B29,VENTAS!$BE:$BE,"<7")+SUMIFS(VENTAS!$O:$O,VENTAS!$AI:$AI,$A$22,VENTAS!$H:$H,$B29,VENTAS!$BE:$BE,"<7")+SUMIFS(VENTAS!$P:$P,VENTAS!$AI:$AI,$A$22,VENTAS!$H:$H,$B29,VENTAS!$BE:$BE,"<7")+SUMIFS(VENTAS!$S:$S,VENTAS!$AI:$AI,$A$22,VENTAS!$H:$H,$B29,VENTAS!$BE:$BE,"<7")+SUMIFS(VENTAS!$V:$V,VENTAS!$AI:$AI,$A$22,VENTAS!$H:$H,$B29,VENTAS!$BE:$BE,"<7") -> 0 | L29: =SUMIFS(VENTAS!$M:$M,VENTAS!$AI:$AI,$A$22,VENTAS!$H:$H,$B29,VENTAS!$BE:$BE,">6")+SUMIFS(VENTAS!$O:$O,VENTAS!$AI:$AI,$A$22,VENTAS!$H:$H,$B29,VENTAS!$BE:$BE,">6")+SUMIFS(VENTAS!$P:$P,VENTAS!$AI:$AI,$A$22,VENTAS!$H:$H,$B29,VENTAS!$BE:$BE,">6")+SUMIFS(VENTAS!$S:$S,VENTAS!$AI:$AI,$A$22,VENTAS!$H:$H,$B29,VENTAS!$BE:$BE,">6")+SUMIFS(VENTAS!$V:$V,VENTAS!$AI:$AI,$A$22,VENTAS!$H:$H,$B29,VENTAS!$BE:$BE,">6") -> 0 | M29: =K29+L29 -> 0
K30: =SUMIFS(VENTAS!$M:$M,VENTAS!$AI:$AI,$A$22,VENTAS!$H:$H,$B30,VENTAS!$BE:$BE,"<7")+SUMIFS(VENTAS!$O:$O,VENTAS!$AI:$AI,$A$22,VENTAS!$H:$H,$B30,VENTAS!$BE:$BE,"<7")+SUMIFS(VENTAS!$P:$P,VENTAS!$AI:$AI,$A$22,VENTAS!$H:$H,$B30,VENTAS!$BE:$BE,"<7")+SUMIFS(VENTAS!$S:$S,VENTAS!$AI:$AI,$A$22,VENTAS!$H:$H,$B30,VENTAS!$BE:$BE,"<7")+SUMIFS(VENTAS!$V:$V,VENTAS!$AI:$AI,$A$22,VENTAS!$H:$H,$B30,VENTAS!$BE:$BE,"<7") -> 0 | L30: =SUMIFS(VENTAS!$M:$M,VENTAS!$AI:$AI,$A$22,VENTAS!$H:$H,$B30,VENTAS!$BE:$BE,">6")+SUMIFS(VENTAS!$O:$O,VENTAS!$AI:$AI,$A$22,VENTAS!$H:$H,$B30,VENTAS!$BE:$BE,">6")+SUMIFS(VENTAS!$P:$P,VENTAS!$AI:$AI,$A$22,VENTAS!$H:$H,$B30,VENTAS!$BE:$BE,">6")+SUMIFS(VENTAS!$S:$S,VENTAS!$AI:$AI,$A$22,VENTAS!$H:$H,$B30,VENTAS!$BE:$BE,">6")+SUMIFS(VENTAS!$V:$V,VENTAS!$AI:$AI,$A$22,VENTAS!$H:$H,$B30,VENTAS!$BE:$BE,">6") -> 0 | M30: =K30+L30 -> 0
A31: BASE IMPONIBLE | K31: =K23+K27 -> 0 | L31: =L23+L27 -> 0 | M31: =K31+L31 -> 0
A32: IMPUESTO A LA RENTA SOBRE FRACCION BASICA | M32: =IF(B21="RIMPE EMPRENDEDOR",VLOOKUP(M31,tbl_Empre,3,1),IF(B21="RIMPE NEGOCIO POPULAR",VLOOKUP(M31,tbl_NegPop,3,1),0)) -> 0
A33: IMPUESTO A LA RENTA SOBRE FRACCION EXCEDENTE | M33: =IF(B21="RIMPE EMPRENDEDOR",(M31-VLOOKUP(M31,tbl_Empre,1,1))*VLOOKUP(M31,tbl_Empre,4,1),0) -> 0
A34: (-) RETENCIONES EN LA FUENTE x SEMESTRE | K34: =-SUMIFS(VENTAS!$AS:$AS,VENTAS!$AI:$AI,$A$22,VENTAS!$BE:$BE,"<7") -> 0 | L34: =-SUMIFS(VENTAS!$AS:$AS,VENTAS!$AI:$AI,$A$22,VENTAS!$BE:$BE,">6") -> 0 | M34: =SUM(K34:L34) -> 0
A35: IMPUESTO RENTA x PAGAR SEMESTRE | K35: =SUM(K32:K34) -> 0 | L35: =SUM(L32:L34) -> 0 | M35: =SUM(M32:M34) -> 0
A37: =Parametros!C140 -> MICROEMPRESA Y ACTIVIDADES INCLUYENTES | K37: 1er SEMESTRE (ENE-JUN) | L37: 2do SEMESTRE (JUL-DIC) | M37: TOTAL ANUAL
A38: SUBTOTAL INGRESOS | K38: =SUM(K39:K41) -> 0 | L38: =SUM(L39:L41) -> 0
B39: 18-Documentos autorizados utilizados en ventas excepto N/C N/D | K39: =SUMIFS(VENTAS!$M:$M,VENTAS!$AI:$AI,$A$22,VENTAS!$H:$H,$B39,VENTAS!$BE:$BE,"<7")+SUMIFS(VENTAS!$O:$O,VENTAS!$AI:$AI,$A$22,VENTAS!$H:$H,$B39,VENTAS!$BE:$BE,"<7")+SUMIFS(VENTAS!$P:$P,VENTAS!$AI:$AI,$A$22,VENTAS!$H:$H,$B39,VENTAS!$BE:$BE,"<7")+SUMIFS(VENTAS!$S:$S,VENTAS!$AI:$AI,$A$22,VENTAS!$H:$H,$B39,VENTAS!$BE:$BE,"<7")+SUMIFS(VENTAS!$V:$V,VENTAS!$AI:$AI,$A$22,VENTAS!$H:$H,$B39,VENTAS!$BE:$BE,"<7") -> 0 | L39: =SUMIFS(VENTAS!$M:$M,VENTAS!$AI:$AI,$A$22,VENTAS!$H:$H,$B39,VENTAS!$BE:$BE,">6")+SUMIFS(VENTAS!$O:$O,VENTAS!$AI:$AI,$A$22,VENTAS!$H:$H,$B39,VENTAS!$BE:$BE,">6")+SUMIFS(VENTAS!$P:$P,VENTAS!$AI:$AI,$A$22,VENTAS!$H:$H,$B39,VENTAS!$BE:$BE,">6")+SUMIFS(VENTAS!$S:$S,VENTAS!$AI:$AI,$A$22,VENTAS!$H:$H,$B39,VENTAS!$BE:$BE,">6")+SUMIFS(VENTAS!$V:$V,VENTAS!$AI:$AI,$A$22,VENTAS!$H:$H,$B39,VENTAS!$BE:$BE,">6") -> 0
B40: 370-Factura operadora transporte / socio | K40: =SUMIFS(VENTAS!$M:$M,VENTAS!$AI:$AI,$A$22,VENTAS!$H:$H,$B40,VENTAS!$BE:$BE,"<7")+SUMIFS(VENTAS!$O:$O,VENTAS!$AI:$AI,$A$22,VENTAS!$H:$H,$B40,VENTAS!$BE:$BE,"<7")+SUMIFS(VENTAS!$P:$P,VENTAS!$AI:$AI,$A$22,VENTAS!$H:$H,$B40,VENTAS!$BE:$BE,"<7")+SUMIFS(VENTAS!$S:$S,VENTAS!$AI:$AI,$A$22,VENTAS!$H:$H,$B40,VENTAS!$BE:$BE,"<7")+SUMIFS(VENTAS!$V:$V,VENTAS!$AI:$AI,$A$22,VENTAS!$H:$H,$B40,VENTAS!$BE:$BE,"<7") -> 0 | L40: =SUMIFS(VENTAS!$M:$M,VENTAS!$AI:$AI,$A$22,VENTAS!$H:$H,$B40,VENTAS!$BE:$BE,">6")+SUMIFS(VENTAS!$O:$O,VENTAS!$AI:$AI,$A$22,VENTAS!$H:$H,$B40,VENTAS!$BE:$BE,">6")+SUMIFS(VENTAS!$P:$P,VENTAS!$AI:$AI,$A$22,VENTAS!$H:$H,$B40,VENTAS!$BE:$BE,">6")+SUMIFS(VENTAS!$S:$S,VENTAS!$AI:$AI,$A$22,VENTAS!$H:$H,$B40,VENTAS!$BE:$BE,">6")+SUMIFS(VENTAS!$V:$V,VENTAS!$AI:$AI,$A$22,VENTAS!$H:$H,$B40,VENTAS!$BE:$BE,">6") -> 0
K41: =SUMIFS(VENTAS!$M:$M,VENTAS!$AI:$AI,$A$22,VENTAS!$H:$H,$B41,VENTAS!$BE:$BE,"<7")+SUMIFS(VENTAS!$O:$O,VENTAS!$AI:$AI,$A$22,VENTAS!$H:$H,$B41,VENTAS!$BE:$BE,"<7")+SUMIFS(VENTAS!$P:$P,VENTAS!$AI:$AI,$A$22,VENTAS!$H:$H,$B41,VENTAS!$BE:$BE,"<7")+SUMIFS(VENTAS!$S:$S,VENTAS!$AI:$AI,$A$22,VENTAS!$H:$H,$B41,VENTAS!$BE:$BE,"<7")+SUMIFS(VENTAS!$V:$V,VENTAS!$AI:$AI,$A$22,VENTAS!$H:$H,$B41,VENTAS!$BE:$BE,"<7") -> 0 | L41: =SUMIFS(VENTAS!$M:$M,VENTAS!$AI:$AI,$A$22,VENTAS!$H:$H,$B41,VENTAS!$BE:$BE,">6")+SUMIFS(VENTAS!$O:$O,VENTAS!$AI:$AI,$A$22,VENTAS!$H:$H,$B41,VENTAS!$BE:$BE,">6")+SUMIFS(VENTAS!$P:$P,VENTAS!$AI:$AI,$A$22,VENTAS!$H:$H,$B41,VENTAS!$BE:$BE,">6")+SUMIFS(VENTAS!$S:$S,VENTAS!$AI:$AI,$A$22,VENTAS!$H:$H,$B41,VENTAS!$BE:$BE,">6")+SUMIFS(VENTAS!$V:$V,VENTAS!$AI:$AI,$A$22,VENTAS!$H:$H,$B41,VENTAS!$BE:$BE,">6") -> 0
A42: (-)DEVOLUCIONES | K42: =SUM(K43:K45) -> 0 | L42: =SUM(L43:L45) -> 0
B43: 04-Nota de credito | K43: =SUMIFS(VENTAS!$M:$M,VENTAS!$AI:$AI,$A$22,VENTAS!$H:$H,$B43,VENTAS!$BE:$BE,"<7")+SUMIFS(VENTAS!$O:$O,VENTAS!$AI:$AI,$A$22,VENTAS!$H:$H,$B43,VENTAS!$BE:$BE,"<7")+SUMIFS(VENTAS!$P:$P,VENTAS!$AI:$AI,$A$22,VENTAS!$H:$H,$B43,VENTAS!$BE:$BE,"<7")+SUMIFS(VENTAS!$S:$S,VENTAS!$AI:$AI,$A$22,VENTAS!$H:$H,$B43,VENTAS!$BE:$BE,"<7")+SUMIFS(VENTAS!$V:$V,VENTAS!$AI:$AI,$A$22,VENTAS!$H:$H,$B43,VENTAS!$BE:$BE,"<7") -> 0 | L43: =SUMIFS(VENTAS!$M:$M,VENTAS!$AI:$AI,$A$22,VENTAS!$H:$H,$B43,VENTAS!$BE:$BE,">6")+SUMIFS(VENTAS!$O:$O,VENTAS!$AI:$AI,$A$22,VENTAS!$H:$H,$B43,VENTAS!$BE:$BE,">6")+SUMIFS(VENTAS!$P:$P,VENTAS!$AI:$AI,$A$22,VENTAS!$H:$H,$B43,VENTAS!$BE:$BE,">6")+SUMIFS(VENTAS!$S:$S,VENTAS!$AI:$AI,$A$22,VENTAS!$H:$H,$B43,VENTAS!$BE:$BE,">6")+SUMIFS(VENTAS!$V:$V,VENTAS!$AI:$AI,$A$22,VENTAS!$H:$H,$B43,VENTAS!$BE:$BE,">6") -> 0
...

Sheet 103
D1: FORMULARIO 103 | I1: DECLARACIÓN DE RETENCIONES EN LA FUENTE DEL IMPUESTO A LA RENTA | AD1: No.
D2: RESOLUCIÓN Nº XXX
A4: 100 IDENTIFICACIÓN DE LA DECLARACIÓN | K4: IMPORTANTE: SÍRVASE LEER INSTRUCCIONES AL REVERSO
C5: =IF(C6,C7,0) -> 0 | D5: =IF(D6,D7,0) -> 0 | E5: =IF(E6,E7,0) -> 0 | F5: =IF(F6,F7,0) -> 4 | G5: =IF(G6,G7,0) -> 0 | H5: =IF(H6,H7,0) -> 0 | I5: =IF(I6,I7,0) -> 0 | J5: =IF(J6,J7,0) -> 0 | ... N5: =IF(N6,N7,0) -> 0 | Q5: SELECCIONE PERIODO | U5: 4 | W5: <<-- Seleccione el periodo a declarar
C6: =IF($U$5=LIQ_IMPUESTOS!$C5,TRUE,FALSE) -> FALSE | D6: =IF($U$5=LIQ_IMPUESTOS!$C6,TRUE,FALSE) -> FALSE | E6: =IF($U$5=LIQ_IMPUESTOS!$C7,TRUE,FALSE) -> FALSE | F6: =IF($U$5=LIQ_IMPUESTOS!$C8,TRUE,FALSE) -> TRUE | G6: =IF($U$5=LIQ_IMPUESTOS!$C9,TRUE,FALSE) -> FALSE | H6: =IF($U$5=LIQ_IMPUESTOS!$C10,TRUE,FALSE) -> FALSE | I6: =IF($U$5=LIQ_IMPUESTOS!$C11,TRUE,FALSE) -> FALSE | J6: =IF($U$5=LIQ_IMPUESTOS!$C12,TRUE,FALSE) -> FALSE | K6: =IF($U$5=LIQ_IMPUESTOS!$C13,TRUE,FALSE) -> FALSE | L6: =IF($U$5=LIQ_IMPUESTOS!$C14,TRUE,FALSE) -> FALSE | M6: =IF($U$5=LIQ_IMPUESTOS!$C15,TRUE,FALSE) -> FALSE | N6: =IF($U$5=LIQ_IMPUESTOS!$C16,TRUE,FALSE) -> FALSE
A7: 101 | B7: MES | C7: 1 | D7: 2 | E7: 3 | F7: 4 | G7: 5 | H7: 6 | I7: 7 | J7: 8 | K7: 9 | L7: 10 | M7: 11 | N7: 12 | Q7: 102 | R7: AÑO | S7: =MID(XLSperiodo,1,1) -> 2 | T7: =MID(XLSperiodo,2,1) -> 0 | U7: =MID(XLSperiodo,3,1) -> 2 | V7: =MID(XLSperiodo,4,1) -> 6 | Y7: 104 | Z7: Nº. DE FORMULARIO QUE SUSTITUYE
A10: 200 IDENTIFICACIÓN DEL SUJETO PASIVO (AGENTE DE RETENCIÓN)
A11: 201 | B11: RUC | O11: 202 | P11: RAZÓN SOCIAL O APELLIDOS Y NOMBRES COMPLETOS
B12: =Parametros!D4 -> 0917809451001 | P12: =Parametros!D5 -> GARCIA RODRIGUEZ CHARLES MILTON
A14: DETALLE DE PAGOS Y RETENCIÓN POR IMPUESTO A LA RENTA
A15: POR PAGOS EFECTUADOS A RESIDENTES Y ESTABLECIMIENTOS PERMANENTES
V16: BASE IMPONIBLE | AC16: VALOR RETENIDO
A17: DERIVADAS DEL TRABAJO Y SERVICIOS PRESTADOS
A18: EN RELACIÓN DE DEPENDENCIA QUE SUPERA O NO LA BASE GRAVADA | V18: 302 | W18: + | X18: =+SUMIFS(COMPRAS!BG:BG,COMPRAS!BF:BF,V18,COMPRAS!DD:DD,"SI")+SUMIFS(COMPRAS!BP:BP,COMPRAS!BO:BO,V18,COMPRAS!DD:DD,"SI")+SUMIFS(COMPRAS!BY:BY,COMPRAS!BX:BX,V18,COMPRAS!DD:DD,"SI") -> 0 | AC18: 352 | AD18: + | AE18: =SUMIFS(COMPRAS!BI:BI,COMPRAS!BF:BF,V18,COMPRAS!DD:DD,"SI")+SUMIFS(COMPRAS!BR:BR,COMPRAS!BO:BO,V18,COMPRAS!DD:DD,"SI")+SUMIFS(COMPRAS!CA:CA,COMPRAS!BX:BX,V18,COMPRAS!DD:DD,"SI") -> 0
A19: SERVICIOS | D19: HONORARIOS PROFESIONALES Y DIETAS | V19: 303 | W19: + | X19: =SUM(X20:AA20) -> 0 | AC19: 353 | AD19: + | AE19: =SUM(AE20:AH20) -> 0
U20: Honorarios profesionales y dietas | V20: 303 | X20: =+SUMIFS(COMPRAS!BG:BG,COMPRAS!BF:BF,V20,COMPRAS!DD:DD,"SI")+SUMIFS(COMPRAS!BP:BP,COMPRAS!BO:BO,V20,COMPRAS!DD:DD,"SI")+SUMIFS(COMPRAS!BY:BY,COMPRAS!BX:BX,V20,COMPRAS!DD:DD,"SI") -> 0 | AE20: =SUMIFS(COMPRAS!BI:BI,COMPRAS!BF:BF,V20,COMPRAS!DD:DD,"SI")+SUMIFS(COMPRAS!BR:BR,COMPRAS!BO:BO,V20,COMPRAS!DD:DD,"SI")+SUMIFS(COMPRAS!CA:CA,COMPRAS!BX:BX,V20,COMPRAS!DD:DD,"SI") -> 0
D21: SERVICIOS PROFESIONALES PRESTADOS POR SOCIEDADES RESIDENTES | V21: 3030 | W21: + | X21: =SUM(X22:AA22) -> 0 | AC21: 3530 | AD21: + | AE21: =SUM(AE22:AH22) -> 0
U22: Servicios profesionales prestados por sociedades residentes | V22: 303A | X22: =+SUMIFS(COMPRAS!BG:BG,COMPRAS!BF:BF,V22,COMPRAS!DD:DD,"SI")+SUMIFS(COMPRAS!BP:BP,COMPRAS!BO:BO,V22,COMPRAS!DD:DD,"SI")+SUMIFS(COMPRAS!BY:BY,COMPRAS!BX:BX,V22,COMPRAS!DD:DD,"SI") -> 0 | AE22: =SUMIFS(COMPRAS!BI:BI,COMPRAS!BF:BF,V22,COMPRAS!DD:DD,"SI")+SUMIFS(COMPRAS!BR:BR,COMPRAS!BO:BO,V22,COMPRAS!DD:DD,"SI")+SUMIFS(COMPRAS!CA:CA,COMPRAS!BX:BX,V22,COMPRAS!DD:DD,"SI") -> 0
D23: PREDOMINA EL INTELECTO | V23: 304 | W23: + | X23: =SUM(X24:AA29) -> 0 | AC23: 354 | AD23: + | AE23: =SUM(AE24:AH29) -> 0
U24: Servicios predomina el intelecto no relacionados con el título profesional | V24: 304 | X24: =+SUMIFS(COMPRAS!BG:BG,COMPRAS!BF:BF,V24,COMPRAS!DD:DD,"SI")+SUMIFS(COMPRAS!BP:BP,COMPRAS!BO:BO,V24,COMPRAS!DD:DD,"SI")+SUMIFS(COMPRAS!BY:BY,COMPRAS!BX:BX,V24,COMPRAS!DD:DD,"SI") -> 0 | AE24: =SUMIFS(COMPRAS!BI:BI,COMPRAS!BF:BF,V24,COMPRAS!DD:DD,"SI")+SUMIFS(COMPRAS!BR:BR,COMPRAS!BO:BO,V24,COMPRAS!DD:DD,"SI")+SUMIFS(COMPRAS!CA:CA,COMPRAS!BX:BX,V24,COMPRAS!DD:DD,"SI") -> 0
U25: Comisiones y demás pagos por servicios predomina intelecto no relacionados con el título profesional | V25: 304A | X25: =+SUMIFS(COMPRAS!BG:BG,COMPRAS!BF:BF,V25,COMPRAS!DD:DD,"SI")+SUMIFS(COMPRAS!BP:BP,COMPRAS!BO:BO,V25,COMPRAS!DD:DD,"SI")+SUMIFS(COMPRAS!BY:BY,COMPRAS!BX:BX,V25,COMPRAS!DD:DD,"SI") -> 0 | AE25: =SUMIFS(COMPRAS!BI:BI,COMPRAS!BF:BF,V25,COMPRAS!DD:DD,"SI")+SUMIFS(COMPRAS!BR:BR,COMPRAS!BO:BO,V25,COMPRAS!DD:DD,"SI")+SUMIFS(COMPRAS!CA:CA,COMPRAS!BX:BX,V25,COMPRAS!DD:DD,"SI") -> 0
U26: Pagos a notarios y registradores de la propiedad y mercantil por sus actividades ejercidas como tales | V26: 304B | X26: =+SUMIFS(COMPRAS!BG:BG,COMPRAS!BF:BF,V26,COMPRAS!DD:DD,"SI")+SUMIFS(COMPRAS!BP:BP,COMPRAS!BO:BO,V26,COMPRAS!DD:DD,"SI")+SUMIFS(COMPRAS!BY:BY,COMPRAS!BX:BX,V26,COMPRAS!DD:DD,"SI") -> 0 | AE26: =SUMIFS(COMPRAS!BI:BI,COMPRAS!BF:BF,V26,COMPRAS!DD:DD,"SI")+SUMIFS(COMPRAS!BR:BR,COMPRAS!BO:BO,V26,COMPRAS!DD:DD,"SI")+SUMIFS(COMPRAS!CA:CA,COMPRAS!BX:BX,V26,COMPRAS!DD:DD,"SI") -> 0
U27: Pagos a deportistas, entrenadores, árbitros, miembros del cuerpo técnico por sus actividades ejercidas como tales | V27: 304C | X27: =+SUMIFS(COMPRAS!BG:BG,COMPRAS!BF:BF,V27,COMPRAS!DD:DD,"SI")+SUMIFS(COMPRAS!BP:BP,COMPRAS!BO:BO,V27,COMPRAS!DD:DD,"SI")+SUMIFS(COMPRAS!BY:BY,COMPRAS!BX:BX,V27,COMPRAS!DD:DD,"SI") -> 0 | AE27: =SUMIFS(COMPRAS!BI:BI,COMPRAS!BF:BF,V27,COMPRAS!DD:DD,"SI")+SUMIFS(COMPRAS!BR:BR,COMPRAS!BO:BO,V27,COMPRAS!DD:DD,"SI")+SUMIFS(COMPRAS!CA:CA,COMPRAS!BX:BX,V27,COMPRAS!DD:DD,"SI") -> 0
U28: Pagos a artistas por sus actividades ejercidas como tales | V28: 304D | X28: =+SUMIFS(COMPRAS!BG:BG,COMPRAS!BF:BF,V28,COMPRAS!DD:DD,"SI")+SUMIFS(COMPRAS!BP:BP,COMPRAS!BO:BO,V28,COMPRAS!DD:DD,"SI")+SUMIFS(COMPRAS!BY:BY,COMPRAS!BX:BX,V28,COMPRAS!DD:DD,"SI") -> 0 | AE28: =SUMIFS(COMPRAS!BI:BI,COMPRAS!BF:BF,V28,COMPRAS!DD:DD,"SI")+SUMIFS(COMPRAS!BR:BR,COMPRAS!BO:BO,V28,COMPRAS!DD:DD,"SI")+SUMIFS(COMPRAS!CA:CA,COMPRAS!BX:BX,V28,COMPRAS!DD:DD,"SI") -> 0
U29: Honorarios y demás pagos por servicios de docencia | V29: 304E | X29: =+SUMIFS(COMPRAS!BG:BG,COMPRAS!BF:BF,V29,COMPRAS!DD:DD,"SI")+SUMIFS(COMPRAS!BP:BP,COMPRAS!BO:BO,V29,COMPRAS!DD:DD,"SI")+SUMIFS(COMPRAS!BY:BY,COMPRAS!BX:BX,V29,COMPRAS!DD:DD,"SI") -> 0 | AE29: =SUMIFS(COMPRAS!BI:BI,COMPRAS!BF:BF,V29,COMPRAS!DD:DD,"SI")+SUMIFS(COMPRAS!BR:BR,COMPRAS!BO:BO,V29,COMPRAS!DD:DD,"SI")+SUMIFS(COMPRAS!CA:CA,COMPRAS!BX:BX,V29,COMPRAS!DD:DD,"SI") -> 0
D30: PREDOMINA MANO DE OBRA | V30: 307 | W30: + | X30: =+SUMIFS(COMPRAS!BG:BG,COMPRAS!BF:BF,V30,COMPRAS!DD:DD,"SI")+SUMIFS(COMPRAS!BP:BP,COMPRAS!BO:BO,V30,COMPRAS!DD:DD,"SI")+SUMIFS(COMPRAS!BY:BY,COMPRAS!BX:BX,V30,COMPRAS!DD:DD,"SI") -> 0 | AC30: 357 | AD30: + | AE30: =SUMIFS(COMPRAS!BI:BI,COMPRAS!BF:BF,V30,COMPRAS!DD:DD,"SI")+SUMIFS(COMPRAS!BR:BR,COMPRAS!BO:BO,V30,COMPRAS!DD:DD,"SI")+SUMIFS(COMPRAS!CA:CA,COMPRAS!BX:BX,V30,COMPRAS!DD:DD,"SI") -> 0
D31: UTILIZACION O APROVECHAMIENTO DE LA IMAGEN O RENOMBRE | V31: 308 | W31: + | X31: =+SUMIFS(COMPRAS!BG:BG,COMPRAS!BF:BF,V31,COMPRAS!DD:DD,"SI")+SUMIFS(COMPRAS!BP:BP,COMPRAS!BO:BO,V31,COMPRAS!DD:DD,"SI")+SUMIFS(COMPRAS!BY:BY,COMPRAS!BX:BX,V31,COMPRAS!DD:DD,"SI") -> 0 | AC31: 358 | AD31: + | AE31: =SUMIFS(COMPRAS!BI:BI,COMPRAS!BF:BF,V31,COMPRAS!DD:DD,"SI")+SUMIFS(COMPRAS!BR:BR,COMPRAS!BO:BO,V31,COMPRAS!DD:DD,"SI")+SUMIFS(COMPRAS!CA:CA,COMPRAS!BX:BX,V31,COMPRAS!DD:DD,"SI") -> 0
D32: PUBLICIDAD Y COMUNICACIÓN | V32: 309 | W32: + | X32: =+SUMIFS(COMPRAS!BG:BG,COMPRAS!BF:BF,V32,COMPRAS!DD:DD,"SI")+SUMIFS(COMPRAS!BP:BP,COMPRAS!BO:BO,V32,COMPRAS!DD:DD,"SI")+SUMIFS(COMPRAS!BY:BY,COMPRAS!BX:BX,V32,COMPRAS!DD:DD,"SI") -> 795 | AC32: 359 | AD32: + | AE32: =SUMIFS(COMPRAS!BI:BI,COMPRAS!BF:BF,V32,COMPRAS!DD:DD,"SI")+SUMIFS(COMPRAS!BR:BR,COMPRAS!BO:BO,V32,COMPRAS!DD:DD,"SI")+SUMIFS(COMPRAS!CA:CA,COMPRAS!BX:BX,V32,COMPRAS!DD:DD,"SI") -> 23.85
D33: TRANSPORTE PRIVADO DE PASAJEROS O SERVICIO PÚBLICO O PRIVADO DE CARGA | V33: 310 | W33: + | X33: =+SUMIFS(COMPRAS!BG:BG,COMPRAS!BF:BF,V33,COMPRAS!DD:DD,"SI")+SUMIFS(COMPRAS!BP:BP,COMPRAS!BO:BO,V33,COMPRAS!DD:DD,"SI")+SUMIFS(COMPRAS!BY:BY,COMPRAS!BX:BX,V33,COMPRAS!DD:DD,"SI") -> 0 | AC33: 360 | AD33: + | AE33: =SUMIFS(COMPRAS!BI:BI,COMPRAS!BF:BF,V33,COMPRAS!DD:DD,"SI")+SUMIFS(COMPRAS!BR:BR,COMPRAS!BO:BO,V33,COMPRAS!DD:DD,"SI")+SUMIFS(COMPRAS!CA:CA,COMPRAS!BX:BX,V33,COMPRAS!DD:DD,"SI") -> 0
A34: A TRAVES DE LIQUIDACIONES DE COMPRA (NIVEL CULTURAL O RUSTICIDAD) | V34: 311 | W34: + | X34: =+SUMIFS(COMPRAS!BG:BG,COMPRAS!BF:BF,V34,COMPRAS!DD:DD,"SI")+SUMIFS(COMPRAS!BP:BP,COMPRAS!BO:BO,V34,COMPRAS!DD:DD,"SI")+SUMIFS(COMPRAS!BY:BY,COMPRAS!BX:BX,V34,COMPRAS!DD:DD,"SI") -> 0 | AC34: 361 | AD34: + | AE34: =SUMIFS(COMPRAS!BI:BI,COMPRAS!BF:BF,V34,COMPRAS!DD:DD,"SI")+SUMIFS(COMPRAS!BR:BR,COMPRAS!BO:BO,V34,COMPRAS!DD:DD,"SI")+SUMIFS(COMPRAS!CA:CA,COMPRAS!BX:BX,V34,COMPRAS!DD:DD,"SI") -> 0
A35: POR BIENES Y SERVICIOS
A36: TRANSFERENCIA DE BIENES MUEBLES DE NATURALEZA CORPORAL | V36: 312 | W36: + | X36: =SUM(X37:AA37) -> 16503.36 | AC36: 362 | AD36: + | AE36: =SUM(AE37:AH37) -> 330.07
